Workbook

Sheet 使い方
A1: このファイルの使い方についてご説明させて頂きます。
A3: ① ファイル形式の変更
A5: ★ | B5: ファイルサイズを小さくする為 「Excel バイナリ ブック」という形式で保存していますが、このまま入力するとデータが正常に保存できない恐れがあるため
B6: 次の手順でファイル形式の変更をお願いいたします。
B7: ・「Excel バイナリ ブック」から「Excel ブック」への変更
C8: 『Excel版専用伝票ファイル』を開きます。（このファイルのことです）
C16: ファイルメニューから「名前を付けて保存」を選択して、ファイルの種類を
C17: 「Excelブック（*.xlsx）」で保存します。
C18: （*.xlsxが選択肢に無い場合は、*.xlsを選択します）
C26: ※請求データの入力作業は、この「Excelブック（*.xlsx もしくは *.xls）」の状態で行ってください。
A29: ② 請求データの入力
A30: ★ | B30: 入力は 請求データ入力 シートで行います。
B31: ・請求基本情報（住所、会社名、取引先ｺｰﾄﾞ、電話番号、課税事業者の方は適格請求書発行事業者登録番号)
B32: ・請求年月を「西暦4桁+月2桁」の数字6桁にて入力
C33: ↓
B34: 入力した内容が「合計請求書」・「個別」シートに反映されますので、入力内容に応じて印刷してください。
A35: ★ | B35: 入力1行につき、1伝票№となります。
B36: 同一工事への請求につきましては1明細1枚とせず、できる限り1枚で作成し、御社様式の明細書を別途添付ください。
A38: 【印刷について】
A40: ★ | B40: 入力完了後「合計請求書」シートと「個別000-000」シートを印刷します。
A42: ★ | B42: 「合計請求書」シート → 印刷用紙に指定はありません。A4にて印刷し、請求印を押印の上ご提出ください。
A44: ★ | B44: 「個別000-000」シート → 弊社指定の用紙に印刷の上、請求印を押印しご提出ください。
E45: 弊社指定用紙：ヒサゴのマルチプリンタ帳票 品番：FSC2013 A4 カラー 3面6穴
F46: ※Amazon、ASKUL等で購入可能です。
A47: ★ | B47: 藤田建装の専用伝票（専用請求書）と同様に、伝票№ひとつにつき、３枚一組となっています。
C48: ② 納品書（原価計算書）
C49: ③ 請求明細書 | G49: この３枚一組を1伝票としてご提出をお願い致します。
C50: ④ 管理伝票 | G50: （専用伝票の①が御社控えとなっている為、Excelでは印刷を省略しています）
A52: ★ | B52: ”１シート 10伝票” になっています。請求データ入力シートに入力した行数分が自動的に印刷範囲に指定されますので
B53: 印刷時に特にページ数を指定する必要はありません。
C54: ↓
B55: ＜複数シートを同時に印刷したい場合＞
B56: シートを複数選択すると、印刷したい部分を一度に印刷できます。
A59: 【お問い合わせの際は】
A61: ★ | B61: ご請求書提出後に藤田建装へお問い合わせを頂く場合は、伝票№をお伝え頂けるとスムーズです。
B62: T№ と書かれている部分が伝票№になります。
A64: 【請求書の再発行について】
B65: 一度藤田建装宛にご提出いただいた請求書を再発行する場合、請求書Noはそのままでも構いませんが、
B66: 印刷した専用伝票の備考欄に
C67: ・「再発行」の文字
...

Sheet 請求データ入力
B1: 【請求基本情報】 | F1: 「※」の箇所は必ず入力ください。
C2: ※住所 | F2: 〒110-0012 東京都台東区竜泉3-40-4 | J2: ※取引先コード | K2: 72130
J4: ※電話番号 | K4: 090-4609-2757
C6: ※会社名 | F6: 有限会社木村左官工業 | J6: 登録番号
J7: ↑適格請求書発行事業者登録番号をお持ちの場合は必ず入力ください。
C9: お手数ですが、初めに請求年月を 西暦4桁＋月2桁 で入力してください。（例：2023年5月の場合 → 202305）
C10: ※請求年月 | F10: 202602 | N10: 非課税事業者の方はこちらの税率を「0％」にしてください。→ | O10: ※消費税率
F11: ↑伝票№の採番に必要な情報の為必ずご入力ください！！ | N11: 税率を変更する場合はこちらを修正ください。→ | O11: 0.1
A12: ｼｰﾄ№ | B12: 連番 | C12: 完成納品年月日 | F12: 御社ご担当者名 | G12: 藤田建装担当者 | H12: 工事ｺｰﾄﾞ | I12: 工事名 | J12: 内容 | K12: 数量 | L12: 単価 単位 | M12: 単価 | N12: 金額 （税抜） | O12: 消費税 | P12: 金額 （税込） | Q12: T№ （伝票№）
C13: 西暦年 | D13: 月 | E13: 日 | H13: (4桁-4桁-2桁)
B14: 例： | C14: 2023 | D14: 4 | E14: 30 | F14: 取引 太郎 | G14: 藤田 太郎 | H14: 9999-9999-01 | I14: 藤田亭 改装工事 | J14: 工事一式 | K14: 1 | L14: 式 | M14: 1375000 | N14: =IF(M14="","",K14*M14) -> 1375000 | O14: =IF(N14="","",ROUNDDOWN(N14*$O$11,0)) -> 137500 | P14: =IF(N14="","",N14+O14) -> 1512500
A15: =B15&"-"&B24 -> 001-010 | B15: 001 | C15: 2026 | D15: 2 | E15: 28 | F15: 木村 正男 | G15: 石川 ほのか 様 | H15: 2302-0258-02 | I15: QB PREMIUM青葉台ﾓﾙﾀﾙ流出補償工事 | J15: 明細書1参照 | K15: 1 | L15: 式 | M15: 30000 | N15: =IF(M15="","",K15*M15) -> 30000 | O15: =IF(N15="","",ROUNDDOWN(N15*$O$11,0)) -> 3000 | P15: =IF(N15="","",N15+O15) -> 33000 | Q15: =CONCATENATE(MID(F10,3,4),B15) -> 2602001
B16: 002 | C16: 2026 | D16: 2 | E16: 28 | F16: 木村 正男 | G16: 石川 ほのか 様 | H16: 2302-0258-03 | I16: QB PREMIUM青葉台東急ｽｸｴｱ店子ﾌﾞﾚｰｶｰ交換工事 | J16: 明細書2参照 | K16: 1 | L16: 式 | M16: 60000 | N16: =IF(M16="","",K16*M16) -> 60000 | O16: =IF(N16="","",ROUNDDOWN(N16*$O$11,0)) -> 6000 | P16: =IF(N16="","",N16+O16) -> 66000 | Q16: =CONCATENATE(MID(F10,3,4),B16) -> 2602002
B17: 003 | C17: 2026 | D17: 2 | E17: 28 | F17: 木村 正男 | G17: 島田 結 様 | H17: 2702-0425-01 | I17: KFCｲｵﾝﾓｰﾙ川口店改装工事 | J17: 明細書3参照 | K17: 1 | L17: 式 | M17: 35000 | N17: =IF(M17="","",K17*M17) -> 35000 | O17: =IF(N17="","",ROUNDDOWN(N17*$O$11,0)) -> 3500 | P17: =IF(N17="","",N17+O17) -> 38500 | Q17: =CONCATENATE(MID(F10,3,4),B17) -> 2602003
B18: 004 | C18: 2026 | D18: 4 | E18: 30 | F18: 園原 | G18: nan 様 | H18: 20260415 | J18: 明細書4参照 | K18: 1 | L18: 式 | M18: 5300 | N18: =IF(M18="","",K18*M18) -> 5300 | O18: =IF(N18="","",ROUNDDOWN(N18*$O$11,0)) -> 530 | P18: =IF(N18="","",N18+O18) -> 5830 | Q18: =CONCATENATE(MID(F10,3,4),B18) -> 2602004
B19: 005 | N19: =IF(M19="","",K19*M19) | O19: =IF(N19="","",ROUNDDOWN(N19*$O$11,0)) | P19: =IF(N19="","",N19+O19) | Q19: =CONCATENATE(MID(F10,3,4),B19) -> 2602005
B20: 006 | N20: =IF(M20="","",K20*M20) | O20: =IF(N20="","",ROUNDDOWN(N20*$O$11,0)) | P20: =IF(N20="","",N20+O20) | Q20: =CONCATENATE(MID(F10,3,4),B20) -> 2602006
B21: 007 | N21: =IF(M21="","",K21*M21) | O21: =IF(N21="","",ROUNDDOWN(N21*$O$11,0)) | P21: =IF(N21="","",N21+O21) | Q21: =CONCATENATE(MID(F10,3,4),B21) -> 2602007
B22: 008 | N22: =IF(M22="","",K22*M22) | O22: =IF(N22="","",ROUNDDOWN(N22*$O$11,0)) | P22: =IF(N22="","",N22+O22) | Q22: =CONCATENATE(MID(F10,3,4),B22) -> 2602008
B23: 009 | N23: =IF(M23="","",K23*M23) | O23: =IF(N23="","",ROUNDDOWN(N23*$O$11,0)) | P23: =IF(N23="","",N23+O23) | Q23: =CONCATENATE(MID(F10,3,4),B23) -> 2602009
B24: 010 | N24: =IF(M24="","",K24*M24) | O24: =IF(N24="","",ROUNDDOWN(N24*$O$11,0)) | P24: =IF(N24="","",N24+O24) | Q24: =CONCATENATE(MID(F10,3,4),B24) -> 2602010
A25: =B25&"-"&B34 -> 011-020 | B25: 011 | N25: =IF(M25="","",K25*M25) | O25: =IF(N25="","",ROUNDDOWN(N25*$O$11,0)) | P25: =IF(N25="","",N25+O25) | Q25: =CONCATENATE(MID(F10,3,4),B25) -> 2602011
B26: 012 | N26: =IF(M26="","",K26*M26) | O26: =IF(N26="","",ROUNDDOWN(N26*$O$11,0)) | P26: =IF(N26="","",N26+O26) | Q26: =CONCATENATE(MID(F10,3,4),B26) -> 2602012
B27: 013 | N27: =IF(M27="","",K27*M27) | O27: =IF(N27="","",ROUNDDOWN(N27*$O$11,0)) | P27: =IF(N27="","",N27+O27) | Q27: =CONCATENATE(MID(F10,3,4),B27) -> 2602013
B28: 014 | N28: =IF(M28="","",K28*M28) | O28: =IF(N28="","",ROUNDDOWN(N28*$O$11,0)) | P28: =IF(N28="","",N28+O28) | Q28: =CONCATENATE(MID(F10,3,4),B28) -> 2602014
B29: 015 | N29: =IF(M29="","",K29*M29) | O29: =IF(N29="","",ROUNDDOWN(N29*$O$11,0)) | P29: =IF(N29="","",N29+O29) | Q29: =CONCATENATE(MID(F10,3,4),B29) -> 2602015
B30: 016 | N30: =IF(M30="","",K30*M30) | O30: =IF(N30="","",ROUNDDOWN(N30*$O$11,0)) | P30: =IF(N30="","",N30+O30) | Q30: =CONCATENATE(MID(F10,3,4),B30) -> 2602016
B31: 017 | N31: =IF(M31="","",K31*M31) | O31: =IF(N31="","",ROUNDDOWN(N31*$O$11,0)) | P31: =IF(N31="","",N31+O31) | Q31: =CONCATENATE(MID(F10,3,4),B31) -> 2602017
B32: 018 | N32: =IF(M32="","",K32*M32) | O32: =IF(N32="","",ROUNDDOWN(N32*$O$11,0)) | P32: =IF(N32="","",N32+O32) | Q32: =CONCATENATE(MID(F10,3,4),B32) -> 2602018
B33: 019 | N33: =IF(M33="","",K33*M33) | O33: =IF(N33="","",ROUNDDOWN(N33*$O$11,0)) | P33: =IF(N33="","",N33+O33) | Q33: =CONCATENATE(MID(F10,3,4),B33) -> 2602019
B34: 020 | N34: =IF(M34="","",K34*M34) | O34: =IF(N34="","",ROUNDDOWN(N34*$O$11,0)) | P34: =IF(N34="","",N34+O34) | Q34: =CONCATENATE(MID(F10,3,4),B34) -> 2602020
A35: =B35&"-"&B44 -> 021-030 | B35: 021 | N35: =IF(M35="","",K35*M35) | O35: =IF(N35="","",ROUNDDOWN(N35*$O$11,0)) | P35: =IF(N35="","",N35+O35) | Q35: =CONCATENATE(MID(F10,3,4),B35) -> 2602021
B36: 022 | N36: =IF(M36="","",K36*M36) | O36: =IF(N36="","",ROUNDDOWN(N36*$O$11,0)) | P36: =IF(N36="","",N36+O36) | Q36: =CONCATENATE(MID(F10,3,4),B36) -> 2602022
B37: 023 | N37: =IF(M37="","",K37*M37) | O37: =IF(N37="","",ROUNDDOWN(N37*$O$11,0)) | P37: =IF(N37="","",N37+O37) | Q37: =CONCATENATE(MID(F10,3,4),B37) -> 2602023
B38: 024 | N38: =IF(M38="","",K38*M38) | O38: =IF(N38="","",ROUNDDOWN(N38*$O$11,0)) | P38: =IF(N38="","",N38+O38) | Q38: =CONCATENATE(MID(F10,3,4),B38) -> 2602024
B39: 025 | N39: =IF(M39="","",K39*M39) | O39: =IF(N39="","",ROUNDDOWN(N39*$O$11,0)) | P39: =IF(N39="","",N39+O39) | Q39: =CONCATENATE(MID(F10,3,4),B39) -> 2602025
B40: 026 | N40: =IF(M40="","",K40*M40) | O40: =IF(N40="","",ROUNDDOWN(N40*$O$11,0)) | P40: =IF(N40="","",N40+O40) | Q40: =CONCATENATE(MID(F10,3,4),B40) -> 2602026
B41: 027 | N41: =IF(M41="","",K41*M41) | O41: =IF(N41="","",ROUNDDOWN(N41*$O$11,0)) | P41: =IF(N41="","",N41+O41) | Q41: =CONCATENATE(MID(F10,3,4),B41) -> 2602027
B42: 028 | N42: =IF(M42="","",K42*M42) | O42: =IF(N42="","",ROUNDDOWN(N42*$O$11,0)) | P42: =IF(N42="","",N42+O42) | Q42: =CONCATENATE(MID(F10,3,4),B42) -> 2602028
B43: 029 | N43: =IF(M43="","",K43*M43) | O43: =IF(N43="","",ROUNDDOWN(N43*$O$11,0)) | P43: =IF(N43="","",N43+O43) | Q43: =CONCATENATE(MID(F10,3,4),B43) -> 2602029
...

Sheet 合計請求書
C1: ■ | E1: =LEFT(E10,4)&"年"&RIGHT(E10,2)&"月分合計請求書" -> 2026年02月分合計請求書 | M1: =G10 -> 72130
M2: ="日付："&LEFT(E10,4)&"年"&RIGHT(E10,2)&"月末日" -> 日付：2026年02月末日 | P2: 印刷範囲 | Q2: =IF(MAX($AP$5:$AP$19)=0,1,MAX($AP$5:$AP$19)) -> 1 | R2: 行目 | S2: 14 | T2: 列目まで印刷する
B3: 〒111-0035
B4: 東京都台東区西浅草1-7-4 | J4: 住所： | K4: =請求データ入力!F2 -> 〒110-0012 東京都台東区竜泉3-40-4
B5: 株式会社藤田建装 御中
J6: 会社名： | K6: =請求データ入力!F6 -> 有限会社木村左官工業 | N6: 印
J8: TEL: | K8: =請求データ入力!K4 -> 090-4609-2757
B10: 請求年月 | E10: =請求データ入力!F10 -> 202602 | F10: 取引先コード | G10: =請求データ入力!K2 -> 72130 | I10: =LEFT(E10,4)&"年"&RIGHT(E10,2)&"月分合計金額(税込)" -> 2026年02月分合計金額(税込) | M10: =SUM(M14:M113) -> 143330
A12: 連番 | B12: 完成納品年月日 | E12: 工事ｺｰﾄﾞ | F12: 工事名 | G12: 内容 | H12: 数量 | I12: 単価 単位 | J12: 単価 | K12: 金額 （税抜） | L12: 消費税 | M12: 金額 （税込） | N12: T№ （伝票№）
B13: 西暦年 | C13: 月 | D13: 日 | E13: (4桁-4桁-2桁)
A14: 001 | B14: =IF(請求データ入力!C15="","",請求データ入力!C15) -> 2026 | C14: =IF(請求データ入力!D15="","",請求データ入力!D15) -> 2 | D14: =IF(請求データ入力!E15="","",請求データ入力!E15) -> 28 | E14: =IF(請求データ入力!H15="","",請求データ入力!H15) -> 2302-0258-02 | F14: =IF(請求データ入力!I15="","",請求データ入力!I15) -> QB PREMIUM青葉台ﾓﾙﾀﾙ流出補償工事 | G14: =IF(請求データ入力!J15="","",請求データ入力!J15) -> 明細書1参照 | H14: =IF(請求データ入力!K15="","",請求データ入力!K15) -> 1 | I14: =IF(請求データ入力!L15="","",請求データ入力!L15) -> 式 | J14: =IF(請求データ入力!M15="","",請求データ入力!M15) -> 30000 | K14: =IF(請求データ入力!N15="","",請求データ入力!N15) -> 30000 | L14: =IF(請求データ入力!O15="","",請求データ入力!O15) -> 3000 | M14: =IF(請求データ入力!P15="","",請求データ入力!P15) -> 33000 | N14: =CONCATENATE(MID(E10,3,4),A14) -> 2602001
A15: 002 | B15: =IF(請求データ入力!C16="","",請求データ入力!C16) -> 2026 | C15: =IF(請求データ入力!D16="","",請求データ入力!D16) -> 2 | D15: =IF(請求データ入力!E16="","",請求データ入力!E16) -> 28 | E15: =IF(請求データ入力!H16="","",請求データ入力!H16) -> 2302-0258-03 | F15: =IF(請求データ入力!I16="","",請求データ入力!I16) -> QB PREMIUM青葉台東急ｽｸｴｱ店子ﾌﾞﾚｰｶｰ交換工事 | G15: =IF(請求データ入力!J16="","",請求データ入力!J16) -> 明細書2参照 | H15: =IF(請求データ入力!K16="","",請求データ入力!K16) -> 1 | I15: =IF(請求データ入力!L16="","",請求データ入力!L16) -> 式 | J15: =IF(請求データ入力!M16="","",請求データ入力!M16) -> 60000 | K15: =IF(請求データ入力!N16="","",請求データ入力!N16) -> 60000 | L15: =IF(請求データ入力!O16="","",請求データ入力!O16) -> 6000 | M15: =IF(請求データ入力!P16="","",請求データ入力!P16) -> 66000 | N15: =CONCATENATE(MID(E10,3,4),A15) -> 2602002
A16: 003 | B16: =IF(請求データ入力!C17="","",請求データ入力!C17) -> 2026 | C16: =IF(請求データ入力!D17="","",請求データ入力!D17) -> 2 | D16: =IF(請求データ入力!E17="","",請求データ入力!E17) -> 28 | E16: =IF(請求データ入力!H17="","",請求データ入力!H17) -> 2702-0425-01 | F16: =IF(請求データ入力!I17="","",請求データ入力!I17) -> KFCｲｵﾝﾓｰﾙ川口店改装工事 | G16: =IF(請求データ入力!J17="","",請求データ入力!J17) -> 明細書3参照 | H16: =IF(請求データ入力!K17="","",請求データ入力!K17) -> 1 | I16: =IF(請求データ入力!L17="","",請求データ入力!L17) -> 式 | J16: =IF(請求データ入力!M17="","",請求データ入力!M17) -> 35000 | K16: =IF(請求データ入力!N17="","",請求データ入力!N17) -> 35000 | L16: =IF(請求データ入力!O17="","",請求データ入力!O17) -> 3500 | M16: =IF(請求データ入力!P17="","",請求データ入力!P17) -> 38500 | N16: =CONCATENATE(MID(E10,3,4),A16) -> 2602003
A17: 004 | B17: =IF(請求データ入力!C18="","",請求データ入力!C18) -> 2026 | C17: =IF(請求データ入力!D18="","",請求データ入力!D18) -> 4 | D17: =IF(請求データ入力!E18="","",請求データ入力!E18) -> 30 | E17: =IF(請求データ入力!H18="","",請求データ入力!H18) -> 20260415 | F17: =IF(請求データ入力!I18="","",請求データ入力!I18) | G17: =IF(請求データ入力!J18="","",請求データ入力!J18) -> 明細書4参照 | H17: =IF(請求データ入力!K18="","",請求データ入力!K18) -> 1 | I17: =IF(請求データ入力!L18="","",請求データ入力!L18) -> 式 | J17: =IF(請求データ入力!M18="","",請求データ入力!M18) -> 5300 | K17: =IF(請求データ入力!N18="","",請求データ入力!N18) -> 5300 | L17: =IF(請求データ入力!O18="","",請求データ入力!O18) -> 530 | M17: =IF(請求データ入力!P18="","",請求データ入力!P18) -> 5830 | N17: =CONCATENATE(MID(E10,3,4),A17) -> 2602004
A18: 005 | B18: =IF(請求データ入力!C19="","",請求データ入力!C19) | C18: =IF(請求データ入力!D19="","",請求データ入力!D19) | D18: =IF(請求データ入力!E19="","",請求データ入力!E19) | E18: =IF(請求データ入力!H19="","",請求データ入力!H19) | F18: =IF(請求データ入力!I19="","",請求データ入力!I19) | G18: =IF(請求データ入力!J19="","",請求データ入力!J19) | H18: =IF(請求データ入力!K19="","",請求データ入力!K19) | I18: =IF(請求データ入力!L19="","",請求データ入力!L19) | J18: =IF(請求データ入力!M19="","",請求データ入力!M19) | K18: =IF(請求データ入力!N19="","",請求データ入力!N19) | L18: =IF(請求データ入力!O19="","",請求データ入力!O19) | M18: =IF(請求データ入力!P19="","",請求データ入力!P19) | N18: =CONCATENATE(MID(E10,3,4),A18) -> 2602005
A19: 006 | B19: =IF(請求データ入力!C20="","",請求データ入力!C20) | C19: =IF(請求データ入力!D20="","",請求データ入力!D20) | D19: =IF(請求データ入力!E20="","",請求データ入力!E20) | E19: =IF(請求データ入力!H20="","",請求データ入力!H20) | F19: =IF(請求データ入力!I20="","",請求データ入力!I20) | G19: =IF(請求データ入力!J20="","",請求データ入力!J20) | H19: =IF(請求データ入力!K20="","",請求データ入力!K20) | I19: =IF(請求データ入力!L20="","",請求データ入力!L20) | J19: =IF(請求データ入力!M20="","",請求データ入力!M20) | K19: =IF(請求データ入力!N20="","",請求データ入力!N20) | L19: =IF(請求データ入力!O20="","",請求データ入力!O20) | M19: =IF(請求データ入力!P20="","",請求データ入力!P20) | N19: =CONCATENATE(MID(E10,3,4),A19) -> 2602006
A20: 007 | B20: =IF(請求データ入力!C21="","",請求データ入力!C21) | C20: =IF(請求データ入力!D21="","",請求データ入力!D21) | D20: =IF(請求データ入力!E21="","",請求データ入力!E21) | E20: =IF(請求データ入力!H21="","",請求データ入力!H21) | F20: =IF(請求データ入力!I21="","",請求データ入力!I21) | G20: =IF(請求データ入力!J21="","",請求データ入力!J21) | H20: =IF(請求データ入力!K21="","",請求データ入力!K21) | I20: =IF(請求データ入力!L21="","",請求データ入力!L21) | J20: =IF(請求データ入力!M21="","",請求データ入力!M21) | K20: =IF(請求データ入力!N21="","",請求データ入力!N21) | L20: =IF(請求データ入力!O21="","",請求データ入力!O21) | M20: =IF(請求データ入力!P21="","",請求データ入力!P21) | N20: =CONCATENATE(MID(E10,3,4),A20) -> 2602007
A21: 008 | B21: =IF(請求データ入力!C22="","",請求データ入力!C22) | C21: =IF(請求データ入力!D22="","",請求データ入力!D22) | D21: =IF(請求データ入力!E22="","",請求データ入力!E22) | E21: =IF(請求データ入力!H22="","",請求データ入力!H22) | F21: =IF(請求データ入力!I22="","",請求データ入力!I22) | G21: =IF(請求データ入力!J22="","",請求データ入力!J22) | H21: =IF(請求データ入力!K22="","",請求データ入力!K22) | I21: =IF(請求データ入力!L22="","",請求データ入力!L22) | J21: =IF(請求データ入力!M22="","",請求データ入力!M22) | K21: =IF(請求データ入力!N22="","",請求データ入力!N22) | L21: =IF(請求データ入力!O22="","",請求データ入力!O22) | M21: =IF(請求データ入力!P22="","",請求データ入力!P22) | N21: =CONCATENATE(MID(E10,3,4),A21) -> 2602008
A22: 009 | B22: =IF(請求データ入力!C23="","",請求データ入力!C23) | C22: =IF(請求データ入力!D23="","",請求データ入力!D23) | D22: =IF(請求データ入力!E23="","",請求データ入力!E23) | E22: =IF(請求データ入力!H23="","",請求データ入力!H23) | F22: =IF(請求データ入力!I23="","",請求データ入力!I23) | G22: =IF(請求データ入力!J23="","",請求データ入力!J23) | H22: =IF(請求データ入力!K23="","",請求データ入力!K23) | I22: =IF(請求データ入力!L23="","",請求データ入力!L23) | J22: =IF(請求データ入力!M23="","",請求データ入力!M23) | K22: =IF(請求データ入力!N23="","",請求データ入力!N23) | L22: =IF(請求データ入力!O23="","",請求データ入力!O23) | M22: =IF(請求データ入力!P23="","",請求データ入力!P23) | N22: =CONCATENATE(MID(E10,3,4),A22) -> 2602009
A23: 010 | B23: =IF(請求データ入力!C24="","",請求データ入力!C24) | C23: =IF(請求データ入力!D24="","",請求データ入力!D24) | D23: =IF(請求データ入力!E24="","",請求データ入力!E24) | E23: =IF(請求データ入力!H24="","",請求データ入力!H24) | F23: =IF(請求データ入力!I24="","",請求データ入力!I24) | G23: =IF(請求データ入力!J24="","",請求データ入力!J24) | H23: =IF(請求データ入力!K24="","",請求データ入力!K24) | I23: =IF(請求データ入力!L24="","",請求データ入力!L24) | J23: =IF(請求データ入力!M24="","",請求データ入力!M24) | K23: =IF(請求データ入力!N24="","",請求データ入力!N24) | L23: =IF(請求データ入力!O24="","",請求データ入力!O24) | M23: =IF(請求データ入力!P24="","",請求データ入力!P24) | N23: =CONCATENATE(MID(E10,3,4),A23) -> 2602010
A24: 011 | B24: =IF(請求データ入力!C25="","",請求データ入力!C25) | C24: =IF(請求データ入力!D25="","",請求データ入力!D25) | D24: =IF(請求データ入力!E25="","",請求データ入力!E25) | E24: =IF(請求データ入力!H25="","",請求データ入力!H25) | F24: =IF(請求データ入力!I25="","",請求データ入力!I25) | G24: =IF(請求データ入力!J25="","",請求データ入力!J25) | H24: =IF(請求データ入力!K25="","",請求データ入力!K25) | I24: =IF(請求データ入力!L25="","",請求データ入力!L25) | J24: =IF(請求データ入力!M25="","",請求データ入力!M25) | K24: =IF(請求データ入力!N25="","",請求データ入力!N25) | L24: =IF(請求データ入力!O25="","",請求データ入力!O25) | M24: =IF(請求データ入力!P25="","",請求データ入力!P25) | N24: =CONCATENATE(MID(E10,3,4),A24) -> 2602011
A25: 012 | B25: =IF(請求データ入力!C26="","",請求データ入力!C26) | C25: =IF(請求データ入力!D26="","",請求データ入力!D26) | D25: =IF(請求データ入力!E26="","",請求データ入力!E26) | E25: =IF(請求データ入力!H26="","",請求データ入力!H26) | F25: =IF(請求データ入力!I26="","",請求データ入力!I26) | G25: =IF(請求データ入力!J26="","",請求データ入力!J26) | H25: =IF(請求データ入力!K26="","",請求データ入力!K26) | I25: =IF(請求データ入力!L26="","",請求データ入力!L26) | J25: =IF(請求データ入力!M26="","",請求データ入力!M26) | K25: =IF(請求データ入力!N26="","",請求データ入力!N26) | L25: =IF(請求データ入力!O26="","",請求データ入力!O26) | M25: =IF(請求データ入力!P26="","",請求データ入力!P26) | N25: =CONCATENATE(MID(E10,3,4),A25) -> 2602012
A26: 013 | B26: =IF(請求データ入力!C27="","",請求データ入力!C27) | C26: =IF(請求データ入力!D27="","",請求データ入力!D27) | D26: =IF(請求データ入力!E27="","",請求データ入力!E27) | E26: =IF(請求データ入力!H27="","",請求データ入力!H27) | F26: =IF(請求データ入力!I27="","",請求データ入力!I27) | G26: =IF(請求データ入力!J27="","",請求データ入力!J27) | H26: =IF(請求データ入力!K27="","",請求データ入力!K27) | I26: =IF(請求データ入力!L27="","",請求データ入力!L27) | J26: =IF(請求データ入力!M27="","",請求データ入力!M27) | K26: =IF(請求データ入力!N27="","",請求データ入力!N27) | L26: =IF(請求データ入力!O27="","",請求データ入力!O27) | M26: =IF(請求データ入力!P27="","",請求データ入力!P27) | N26: =CONCATENATE(MID(E10,3,4),A26) -> 2602013
A27: 014 | B27: =IF(請求データ入力!C28="","",請求データ入力!C28) | C27: =IF(請求データ入力!D28="","",請求データ入力!D28) | D27: =IF(請求データ入力!E28="","",請求データ入力!E28) | E27: =IF(請求データ入力!H28="","",請求データ入力!H28) | F27: =IF(請求データ入力!I28="","",請求データ入力!I28) | G27: =IF(請求データ入力!J28="","",請求データ入力!J28) | H27: =IF(請求データ入力!K28="","",請求データ入力!K28) | I27: =IF(請求データ入力!L28="","",請求データ入力!L28) | J27: =IF(請求データ入力!M28="","",請求データ入力!M28) | K27: =IF(請求データ入力!N28="","",請求データ入力!N28) | L27: =IF(請求データ入力!O28="","",請求データ入力!O28) | M27: =IF(請求データ入力!P28="","",請求データ入力!P28) | N27: =CONCATENATE(MID(E10,3,4),A27) -> 2602014
A28: 015 | B28: =IF(請求データ入力!C29="","",請求データ入力!C29) | C28: =IF(請求データ入力!D29="","",請求データ入力!D29) | D28: =IF(請求データ入力!E29="","",請求データ入力!E29) | E28: =IF(請求データ入力!H29="","",請求データ入力!H29) | F28: =IF(請求データ入力!I29="","",請求データ入力!I29) | G28: =IF(請求データ入力!J29="","",請求データ入力!J29) | H28: =IF(請求データ入力!K29="","",請求データ入力!K29) | I28: =IF(請求データ入力!L29="","",請求データ入力!L29) | J28: =IF(請求データ入力!M29="","",請求データ入力!M29) | K28: =IF(請求データ入力!N29="","",請求データ入力!N29) | L28: =IF(請求データ入力!O29="","",請求データ入力!O29) | M28: =IF(請求データ入力!P29="","",請求データ入力!P29) | N28: =CONCATENATE(MID(E10,3,4),A28) -> 2602015
A29: 016 | B29: =IF(請求データ入力!C30="","",請求データ入力!C30) | C29: =IF(請求データ入力!D30="","",請求データ入力!D30) | D29: =IF(請求データ入力!E30="","",請求データ入力!E30) | E29: =IF(請求データ入力!H30="","",請求データ入力!H30) | F29: =IF(請求データ入力!I30="","",請求データ入力!I30) | G29: =IF(請求データ入力!J30="","",請求データ入力!J30) | H29: =IF(請求データ入力!K30="","",請求データ入力!K30) | I29: =IF(請求データ入力!L30="","",請求データ入力!L30) | J29: =IF(請求データ入力!M30="","",請求データ入力!M30) | K29: =IF(請求データ入力!N30="","",請求データ入力!N30) | L29: =IF(請求データ入力!O30="","",請求データ入力!O30) | M29: =IF(請求データ入力!P30="","",請求データ入力!P30) | N29: =CONCATENATE(MID(E10,3,4),A29) -> 2602016
A30: 017 | B30: =IF(請求データ入力!C31="","",請求データ入力!C31) | C30: =IF(請求データ入力!D31="","",請求データ入力!D31) | D30: =IF(請求データ入力!E31="","",請求データ入力!E31) | E30: =IF(請求データ入力!H31="","",請求データ入力!H31) | F30: =IF(請求データ入力!I31="","",請求データ入力!I31) | G30: =IF(請求データ入力!J31="","",請求データ入力!J31) | H30: =IF(請求データ入力!K31="","",請求データ入力!K31) | I30: =IF(請求データ入力!L31="","",請求データ入力!L31) | J30: =IF(請求データ入力!M31="","",請求データ入力!M31) | K30: =IF(請求データ入力!N31="","",請求データ入力!N31) | L30: =IF(請求データ入力!O31="","",請求データ入力!O31) | M30: =IF(請求データ入力!P31="","",請求データ入力!P31) | N30: =CONCATENATE(MID(E10,3,4),A30) -> 2602017
A31: 018 | B31: =IF(請求データ入力!C32="","",請求データ入力!C32) | C31: =IF(請求データ入力!D32="","",請求データ入力!D32) | D31: =IF(請求データ入力!E32="","",請求データ入力!E32) | E31: =IF(請求データ入力!H32="","",請求データ入力!H32) | F31: =IF(請求データ入力!I32="","",請求データ入力!I32) | G31: =IF(請求データ入力!J32="","",請求データ入力!J32) | H31: =IF(請求データ入力!K32="","",請求データ入力!K32) | I31: =IF(請求データ入力!L32="","",請求データ入力!L32) | J31: =IF(請求データ入力!M32="","",請求データ入力!M32) | K31: =IF(請求データ入力!N32="","",請求データ入力!N32) | L31: =IF(請求データ入力!O32="","",請求データ入力!O32) | M31: =IF(請求データ入力!P32="","",請求データ入力!P32) | N31: =CONCATENATE(MID(E10,3,4),A31) -> 2602018
A32: 019 | B32: =IF(請求データ入力!C33="","",請求データ入力!C33) | C32: =IF(請求データ入力!D33="","",請求データ入力!D33) | D32: =IF(請求データ入力!E33="","",請求データ入力!E33) | E32: =IF(請求データ入力!H33="","",請求データ入力!H33) | F32: =IF(請求データ入力!I33="","",請求データ入力!I33) | G32: =IF(請求データ入力!J33="","",請求データ入力!J33) | H32: =IF(請求データ入力!K33="","",請求データ入力!K33) | I32: =IF(請求データ入力!L33="","",請求データ入力!L33) | J32: =IF(請求データ入力!M33="","",請求データ入力!M33) | K32: =IF(請求データ入力!N33="","",請求データ入力!N33) | L32: =IF(請求データ入力!O33="","",請求データ入力!O33) | M32: =IF(請求データ入力!P33="","",請求データ入力!P33) | N32: =CONCATENATE(MID(E10,3,4),A32) -> 2602019
A33: 020 | B33: =IF(請求データ入力!C34="","",請求データ入力!C34) | C33: =IF(請求データ入力!D34="","",請求データ入力!D34) | D33: =IF(請求データ入力!E34="","",請求データ入力!E34) | E33: =IF(請求データ入力!H34="","",請求データ入力!H34) | F33: =IF(請求データ入力!I34="","",請求データ入力!I34) | G33: =IF(請求データ入力!J34="","",請求データ入力!J34) | H33: =IF(請求データ入力!K34="","",請求データ入力!K34) | I33: =IF(請求データ入力!L34="","",請求データ入力!L34) | J33: =IF(請求データ入力!M34="","",請求データ入力!M34) | K33: =IF(請求データ入力!N34="","",請求データ入力!N34) | L33: =IF(請求データ入力!O34="","",請求データ入力!O34) | M33: =IF(請求データ入力!P34="","",請求データ入力!P34) | N33: =CONCATENATE(MID(E10,3,4),A33) -> 2602020
A34: 021 | B34: =IF(請求データ入力!C35="","",請求データ入力!C35) | C34: =IF(請求データ入力!D35="","",請求データ入力!D35) | D34: =IF(請求データ入力!E35="","",請求データ入力!E35) | E34: =IF(請求データ入力!H35="","",請求データ入力!H35) | F34: =IF(請求データ入力!I35="","",請求データ入力!I35) | G34: =IF(請求データ入力!J35="","",請求データ入力!J35) | H34: =IF(請求データ入力!K35="","",請求データ入力!K35) | I34: =IF(請求データ入力!L35="","",請求データ入力!L35) | J34: =IF(請求データ入力!M35="","",請求データ入力!M35) | K34: =IF(請求データ入力!N35="","",請求データ入力!N35) | L34: =IF(請求データ入力!O35="","",請求データ入力!O35) | M34: =IF(請求データ入力!P35="","",請求データ入力!P35) | N34: =CONCATENATE(MID(E10,3,4),A34) -> 2602021
A35: 022 | B35: =IF(請求データ入力!C36="","",請求データ入力!C36) | C35: =IF(請求データ入力!D36="","",請求データ入力!D36) | D35: =IF(請求データ入力!E36="","",請求データ入力!E36) | E35: =IF(請求データ入力!H36="","",請求データ入力!H36) | F35: =IF(請求データ入力!I36="","",請求データ入力!I36) | G35: =IF(請求データ入力!J36="","",請求データ入力!J36) | H35: =IF(請求データ入力!K36="","",請求データ入力!K36) | I35: =IF(請求データ入力!L36="","",請求データ入力!L36) | J35: =IF(請求データ入力!M36="","",請求データ入力!M36) | K35: =IF(請求データ入力!N36="","",請求データ入力!N36) | L35: =IF(請求データ入力!O36="","",請求データ入力!O36) | M35: =IF(請求データ入力!P36="","",請求データ入力!P36) | N35: =CONCATENATE(MID(E10,3,4),A35) -> 2602022
A36: 023 | B36: =IF(請求データ入力!C37="","",請求データ入力!C37) | C36: =IF(請求データ入力!D37="","",請求データ入力!D37) | D36: =IF(請求データ入力!E37="","",請求データ入力!E37) | E36: =IF(請求データ入力!H37="","",請求データ入力!H37) | F36: =IF(請求データ入力!I37="","",請求データ入力!I37) | G36: =IF(請求データ入力!J37="","",請求データ入力!J37) | H36: =IF(請求データ入力!K37="","",請求データ入力!K37) | I36: =IF(請求データ入力!L37="","",請求データ入力!L37) | J36: =IF(請求データ入力!M37="","",請求データ入力!M37) | K36: =IF(請求データ入力!N37="","",請求データ入力!N37) | L36: =IF(請求データ入力!O37="","",請求データ入力!O37) | M36: =IF(請求データ入力!P37="","",請求データ入力!P37) | N36: =CONCATENATE(MID(E10,3,4),A36) -> 2602023
A37: 024 | B37: =IF(請求データ入力!C38="","",請求データ入力!C38) | C37: =IF(請求データ入力!D38="","",請求データ入力!D38) | D37: =IF(請求データ入力!E38="","",請求データ入力!E38) | E37: =IF(請求データ入力!H38="","",請求データ入力!H38) | F37: =IF(請求データ入力!I38="","",請求データ入力!I38) | G37: =IF(請求データ入力!J38="","",請求データ入力!J38) | H37: =IF(請求データ入力!K38="","",請求データ入力!K38) | I37: =IF(請求データ入力!L38="","",請求データ入力!L38) | J37: =IF(請求データ入力!M38="","",請求データ入力!M38) | K37: =IF(請求データ入力!N38="","",請求データ入力!N38) | L37: =IF(請求データ入力!O38="","",請求データ入力!O38) | M37: =IF(請求データ入力!P38="","",請求データ入力!P38) | N37: =CONCATENATE(MID(E10,3,4),A37) -> 2602024
A38: 025 | B38: =IF(請求データ入力!C39="","",請求データ入力!C39) | C38: =IF(請求データ入力!D39="","",請求データ入力!D39) | D38: =IF(請求データ入力!E39="","",請求データ入力!E39) | E38: =IF(請求データ入力!H39="","",請求データ入力!H39) | F38: =IF(請求データ入力!I39="","",請求データ入力!I39) | G38: =IF(請求データ入力!J39="","",請求データ入力!J39) | H38: =IF(請求データ入力!K39="","",請求データ入力!K39) | I38: =IF(請求データ入力!L39="","",請求データ入力!L39) | J38: =IF(請求データ入力!M39="","",請求データ入力!M39) | K38: =IF(請求データ入力!N39="","",請求データ入力!N39) | L38: =IF(請求データ入力!O39="","",請求データ入力!O39) | M38: =IF(請求データ入力!P39="","",請求データ入力!P39) | N38: =CONCATENATE(MID(E10,3,4),A38) -> 2602025
A39: 026 | B39: =IF(請求データ入力!C40="","",請求データ入力!C40) | C39: =IF(請求データ入力!D40="","",請求データ入力!D40) | D39: =IF(請求データ入力!E40="","",請求データ入力!E40) | E39: =IF(請求データ入力!H40="","",請求データ入力!H40) | F39: =IF(請求データ入力!I40="","",請求データ入力!I40) | G39: =IF(請求データ入力!J40="","",請求データ入力!J40) | H39: =IF(請求データ入力!K40="","",請求データ入力!K40) | I39: =IF(請求データ入力!L40="","",請求データ入力!L40) | J39: =IF(請求データ入力!M40="","",請求データ入力!M40) | K39: =IF(請求データ入力!N40="","",請求データ入力!N40) | L39: =IF(請求データ入力!O40="","",請求データ入力!O40) | M39: =IF(請求データ入力!P40="","",請求データ入力!P40) | N39: =CONCATENATE(MID(E10,3,4),A39) -> 2602026
A40: 027 | B40: =IF(請求データ入力!C41="","",請求データ入力!C41) | C40: =IF(請求データ入力!D41="","",請求データ入力!D41) | D40: =IF(請求データ入力!E41="","",請求データ入力!E41) | E40: =IF(請求データ入力!H41="","",請求データ入力!H41) | F40: =IF(請求データ入力!I41="","",請求データ入力!I41) | G40: =IF(請求データ入力!J41="","",請求データ入力!J41) | H40: =IF(請求データ入力!K41="","",請求データ入力!K41) | I40: =IF(請求データ入力!L41="","",請求データ入力!L41) | J40: =IF(請求データ入力!M41="","",請求データ入力!M41) | K40: =IF(請求データ入力!N41="","",請求データ入力!N41) | L40: =IF(請求データ入力!O41="","",請求データ入力!O41) | M40: =IF(請求データ入力!P41="","",請求データ入力!P41) | N40: =CONCATENATE(MID(E10,3,4),A40) -> 2602027
A41: 028 | B41: =IF(請求データ入力!C42="","",請求データ入力!C42) | C41: =IF(請求データ入力!D42="","",請求データ入力!D42) | D41: =IF(請求データ入力!E42="","",請求データ入力!E42) | E41: =IF(請求データ入力!H42="","",請求データ入力!H42) | F41: =IF(請求データ入力!I42="","",請求データ入力!I42) | G41: =IF(請求データ入力!J42="","",請求データ入力!J42) | H41: =IF(請求データ入力!K42="","",請求データ入力!K42) | I41: =IF(請求データ入力!L42="","",請求データ入力!L42) | J41: =IF(請求データ入力!M42="","",請求データ入力!M42) | K41: =IF(請求データ入力!N42="","",請求データ入力!N42) | L41: =IF(請求データ入力!O42="","",請求データ入力!O42) | M41: =IF(請求データ入力!P42="","",請求データ入力!P42) | N41: =CONCATENATE(MID(E10,3,4),A41) -> 2602028
A42: 029 | B42: =IF(請求データ入力!C43="","",請求データ入力!C43) | C42: =IF(請求データ入力!D43="","",請求データ入力!D43) | D42: =IF(請求データ入力!E43="","",請求データ入力!E43) | E42: =IF(請求データ入力!H43="","",請求データ入力!H43) | F42: =IF(請求データ入力!I43="","",請求データ入力!I43) | G42: =IF(請求データ入力!J43="","",請求データ入力!J43) | H42: =IF(請求データ入力!K43="","",請求データ入力!K43) | I42: =IF(請求データ入力!L43="","",請求データ入力!L43) | J42: =IF(請求データ入力!M43="","",請求データ入力!M43) | K42: =IF(請求データ入力!N43="","",請求データ入力!N43) | L42: =IF(請求データ入力!O43="","",請求データ入力!O43) | M42: =IF(請求データ入力!P43="","",請求データ入力!P43) | N42: =CONCATENATE(MID(E10,3,4),A42) -> 2602029
A43: 030 | B43: =IF(請求データ入力!C44="","",請求データ入力!C44) | C43: =IF(請求データ入力!D44="","",請求データ入力!D44) | D43: =IF(請求データ入力!E44="","",請求データ入力!E44) | E43: =IF(請求データ入力!H44="","",請求データ入力!H44) | F43: =IF(請求データ入力!I44="","",請求データ入力!I44) | G43: =IF(請求データ入力!J44="","",請求データ入力!J44) | H43: =IF(請求データ入力!K44="","",請求データ入力!K44) | I43: =IF(請求データ入力!L44="","",請求データ入力!L44) | J43: =IF(請求データ入力!M44="","",請求データ入力!M44) | K43: =IF(請求データ入力!N44="","",請求データ入力!N44) | L43: =IF(請求データ入力!O44="","",請求データ入力!O44) | M43: =IF(請求データ入力!P44="","",請求データ入力!P44) | N43: =CONCATENATE(MID(E10,3,4),A43) -> 2602030
...

Sheet 個別001-010
B1: ② 納品書 （原価計算書） | P1: ㈱藤田建装 現場担当→課管理 | AA1: 備 考 | AM1: 301
E2: ◆ 内 容 | N2: ◆ 数 量 | R2: ◆ 単 価 | V2: ◆ 金 額 | AO2: 印刷範囲 | AP2: =IF(MAX($AP$5:$AP$19)=0,1,MAX($AP$5:$AP$19)) -> 248 | AQ2: 行目 | AR2: =IF(AP2=1,1,38) -> 38 | AS2: 列目まで印刷する
B3: =請求データ入力!J15 -> 明細書1参照 | N3: =請求データ入力!K15 -> 1 | P3: =請求データ入力!L15 -> 式 | R3: =請求データ入力!M15 -> 30000 | V3: =請求データ入力!N15 -> 30000
AA4: 差替No. | AO4: 伝票№連番 | AP4: 行数
AA5: 未請求No. | AO5: 001 | AP5: =IF(VLOOKUP(AO5,請求データ入力!$B$15:$P$114,9)=0,"",62) -> 62
AA6: 経理責任者 | AE6: 経理担当 | AI6: 現場担当 | AO6: 002 | AP6: =IF(VLOOKUP(AO6,請求データ入力!$B$15:$P$114,9)=0,"",124) -> 124
AO7: 003 | AP7: =IF(VLOOKUP(AO7,請求データ入力!$B$15:$P$114,9)=0,"",186) -> 186
AO8: 004 | AP8: =IF(VLOOKUP(AO8,請求データ入力!$B$15:$P$114,9)=0,"",248) -> 248
AO9: 005 | AP9: =IF(VLOOKUP(AO9,請求データ入力!$B$15:$P$114,9)=0,"",310)
B10: ◆取引先名/コード | G10: =請求データ入力!$K$2 -> 72130 | L10: 登録番号 | R10: ◆計（税抜） | AO10: 006 | AP10: =IF(VLOOKUP(AO10,請求データ入力!$B$15:$P$114,9)=0,"",372)
L11: =請求データ入力!$K$6 -> 0 | V11: =請求データ入力!N15 -> 30000
B12: =請求データ入力!$F$2 -> 〒110-0012 東京都台東区竜泉3-40-4 | R12: ◆消費税 | AO12: 007 | AP12: =IF(VLOOKUP(AO12,請求データ入力!$B$15:$P$114,9)=0,"",434)
R13: （切捨） | T13: =請求データ入力!$O$11 -> 0.1 | V13: =請求データ入力!O15 -> 3000
B14: =請求データ入力!$F$6 -> 有限会社木村左官工業 | R14: ◆税込合計金額 | AO14: 008 | AP14: =IF(VLOOKUP(AO14,請求データ入力!$B$15:$P$114,9)=0,"",496)
V15: =請求データ入力!P15 -> 33000 | AC15: 明細 （ 有 ・ 無 ）
R16: ◆取引先担当者 | V16: ◆完成納品年月日 | AC16: 検 算 | AI16: INPUT | AO16: 009 | AP16: =IF(VLOOKUP(AO16,請求データ入力!$B$15:$P$114,9)=0,"",558)
B17: ="TEL："&請求データ入力!$K$4 -> TEL：090-4609-2757 | R17: =請求データ入力!F15 -> 木村 正男 | V17: =CONCATENATE(請求データ入力!C15,"/",請求データ入力!D15,"/",請求データ入力!E15) -> 2026/2/28
B18: ◆工事コード/工事名 | R18: ◆藤田建装担当者 | AO18: 010 | AP18: =IF(VLOOKUP(AO18,請求データ入力!$B$15:$P$114,9)=0,"",620)
B19: =請求データ入力!H15 -> 2302-0258-02 | G19: =請求データ入力!I15 -> QB PREMIUM青葉台ﾓﾙﾀﾙ流出補償工事 | R19: =請求データ入力!G15 -> 石川 ほのか 様 | V19: T№ | W19: =請求データ入力!Q15 -> 2602001
B22: ③ 請求明細書 | P22: ㈱藤田建装 経理管理 | AA22: 備 考
E23: ◆ 内 容 | N23: ◆ 数 量 | R23: ◆ 単 価 | V23: ◆ 金 額
B24: =B3 -> 明細書1参照 | N24: =N3 -> 1 | P24: =P3 -> 式 | R24: =R3 -> 30000 | V24: =V3 -> 30000
AA25: 差替No.
AA26: 未請求No.
AA27: 経理責任者 | AE27: 経理担当 | AI27: 現場担当
B31: ◆取引先名/コード | G31: =請求データ入力!$K$2 -> 72130 | L31: 登録番号 | R31: ◆計（税抜）
L32: =請求データ入力!$K$6 -> 0 | V32: =V11 -> 30000
B33: =請求データ入力!$F$2 -> 〒110-0012 東京都台東区竜泉3-40-4 | R33: ◆消費税
R34: （切捨） | T34: =請求データ入力!$O$11 -> 0.1 | V34: =V13 -> 3000
B35: =請求データ入力!$F$6 -> 有限会社木村左官工業 | R35: ◆税込合計金額
V36: =V15 -> 33000 | AC36: 明細 （ 有 ・ 無 ）
R37: ◆取引先担当者 | V37: ◆完成納品年月日 | AC37: 検 算 | AI37: INPUT
B38: ="TEL："&請求データ入力!$K$4 -> TEL：090-4609-2757 | R38: =R17 -> 木村 正男 | V38: =V17 -> 2026/2/28
B39: ◆工事コード/工事名 | R39: ◆藤田建装担当者
B40: =B19 -> 2302-0258-02 | G40: =G19 -> QB PREMIUM青葉台ﾓﾙﾀﾙ流出補償工事 | R40: =R19 -> 石川 ほのか 様 | V40: T№ | W40: =W19 -> 2602001
B43: ④ 管理伝票 | P43: ㈱藤田建装 事業部管理 | AA43: 備 考
E44: ◆ 内 容 | N44: ◆ 数 量 | R44: ◆ 単 価 | V44: ◆ 金 額
B45: =B24 -> 明細書1参照 | N45: =N24 -> 1 | P45: =P24 -> 式 | R45: =R24 -> 30000 | V45: =V24 -> 30000
AA46: 差替No.
AA47: 未請求No.
...

Sheet 個別011-020
B1: ② 納品書 （原価計算書） | P1: ㈱藤田建装 現場担当→課管理 | AA1: 備 考 | AM1: 311
E2: ◆ 内 容 | N2: ◆ 数 量 | R2: ◆ 単 価 | V2: ◆ 金 額 | AO2: 印刷範囲 | AP2: =IF(MAX($AP$5:$AP$19)=0,1,MAX($AP$5:$AP$19)) -> 1 | AQ2: 行目 | AR2: =IF(AP2=1,1,38) -> 1 | AS2: 列目まで印刷する
B3: =請求データ入力!J25 -> 0 | N3: =請求データ入力!K25 -> 0 | P3: =請求データ入力!L25 -> 0 | R3: =請求データ入力!M25 -> 0 | V3: =請求データ入力!N25
AA4: 差替No. | AO4: 伝票№連番 | AP4: 行数
AA5: 未請求No. | AO5: 011 | AP5: =IF(VLOOKUP(AO5,請求データ入力!$B$15:$P$114,9)=0,"",62)
AA6: 経理責任者 | AE6: 経理担当 | AI6: 現場担当 | AO6: 012 | AP6: =IF(VLOOKUP(AO6,請求データ入力!$B$15:$P$114,9)=0,"",124)
AO7: 013 | AP7: =IF(VLOOKUP(AO7,請求データ入力!$B$15:$P$114,9)=0,"",186)
AO8: 014 | AP8: =IF(VLOOKUP(AO8,請求データ入力!$B$15:$P$114,9)=0,"",248)
AO9: 015 | AP9: =IF(VLOOKUP(AO9,請求データ入力!$B$15:$P$114,9)=0,"",310)
B10: ◆取引先名/コード | G10: =請求データ入力!$K$2 -> 72130 | L10: 登録番号 | R10: ◆計（税抜） | AO10: 016 | AP10: =IF(VLOOKUP(AO10,請求データ入力!$B$15:$P$114,9)=0,"",372)
L11: =請求データ入力!$K$6 -> 0 | V11: =請求データ入力!N25
B12: =請求データ入力!$F$2 -> 〒110-0012 東京都台東区竜泉3-40-4 | R12: ◆消費税 | AO12: 017 | AP12: =IF(VLOOKUP(AO12,請求データ入力!$B$15:$P$114,9)=0,"",434)
R13: （切捨） | T13: =請求データ入力!$O$11 -> 0.1 | V13: =請求データ入力!O25
B14: =請求データ入力!$F$6 -> 有限会社木村左官工業 | R14: ◆税込合計金額 | AO14: 018 | AP14: =IF(VLOOKUP(AO14,請求データ入力!$B$15:$P$114,9)=0,"",496)
V15: =請求データ入力!P25 | AC15: 明細 （ 有 ・ 無 ）
R16: ◆取引先担当者 | V16: ◆完成納品年月日 | AC16: 検 算 | AI16: INPUT | AO16: 019 | AP16: =IF(VLOOKUP(AO16,請求データ入力!$B$15:$P$114,9)=0,"",558)
B17: ="TEL："&請求データ入力!$K$4 -> TEL：090-4609-2757 | R17: =請求データ入力!F25 -> 0 | V17: =CONCATENATE(請求データ入力!C25,"/",請求データ入力!D25,"/",請求データ入力!E25) -> //
B18: ◆工事コード/工事名 | R18: ◆藤田建装担当者 | AO18: 020 | AP18: =IF(VLOOKUP(AO18,請求データ入力!$B$15:$P$114,9)=0,"",620)
B19: =請求データ入力!H25 -> 0 | G19: =請求データ入力!I25 -> 0 | R19: =請求データ入力!G25 -> 0 | V19: T№ | W19: =請求データ入力!Q25 -> 2602011
B22: ③ 請求明細書 | P22: ㈱藤田建装 経理管理 | AA22: 備 考
E23: ◆ 内 容 | N23: ◆ 数 量 | R23: ◆ 単 価 | V23: ◆ 金 額
B24: =B3 -> 0 | N24: =N3 -> 0 | P24: =P3 -> 0 | R24: =R3 -> 0 | V24: =V3
AA25: 差替No.
AA26: 未請求No.
AA27: 経理責任者 | AE27: 経理担当 | AI27: 現場担当
B31: ◆取引先名/コード | G31: =請求データ入力!$K$2 -> 72130 | L31: 登録番号 | R31: ◆計（税抜）
L32: =請求データ入力!$K$6 -> 0 | V32: =V11
B33: =請求データ入力!$F$2 -> 〒110-0012 東京都台東区竜泉3-40-4 | R33: ◆消費税
R34: （切捨） | T34: =請求データ入力!$O$11 -> 0.1 | V34: =V13
B35: =請求データ入力!$F$6 -> 有限会社木村左官工業 | R35: ◆税込合計金額
V36: =V15 | AC36: 明細 （ 有 ・ 無 ）
R37: ◆取引先担当者 | V37: ◆完成納品年月日 | AC37: 検 算 | AI37: INPUT
B38: ="TEL："&請求データ入力!$K$4 -> TEL：090-4609-2757 | R38: =R17 -> 0 | V38: =V17 -> //
B39: ◆工事コード/工事名 | R39: ◆藤田建装担当者
B40: =B19 -> 0 | G40: =G19 -> 0 | R40: =R19 -> 0 | V40: T№ | W40: =W19 -> 2602011
B43: ④ 管理伝票 | P43: ㈱藤田建装 事業部管理 | AA43: 備 考
E44: ◆ 内 容 | N44: ◆ 数 量 | R44: ◆ 単 価 | V44: ◆ 金 額
B45: =B24 -> 0 | N45: =N24 -> 0 | P45: =P24 -> 0 | R45: =R24 -> 0 | V45: =V24
AA46: 差替No.
AA47: 未請求No.
...

Sheet 個別021-030
B1: ② 納品書 （原価計算書） | P1: ㈱藤田建装 現場担当→課管理 | AA1: 備 考 | AM1: 321
E2: ◆ 内 容 | N2: ◆ 数 量 | R2: ◆ 単 価 | V2: ◆ 金 額 | AO2: 印刷範囲 | AP2: =IF(MAX($AP$5:$AP$19)=0,1,MAX($AP$5:$AP$19)) -> 1 | AQ2: 行目 | AR2: =IF(AP2=1,1,38) -> 1 | AS2: 列目まで印刷する
B3: =請求データ入力!J35 -> 0 | N3: =請求データ入力!K35 -> 0 | P3: =請求データ入力!L35 -> 0 | R3: =請求データ入力!M35 -> 0 | V3: =請求データ入力!N35
AA4: 差替No. | AO4: 伝票№連番 | AP4: 行数
AA5: 未請求No. | AO5: 021 | AP5: =IF(VLOOKUP(AO5,請求データ入力!$B$15:$P$114,9)=0,"",62)
AA6: 経理責任者 | AE6: 経理担当 | AI6: 現場担当 | AO6: 022 | AP6: =IF(VLOOKUP(AO6,請求データ入力!$B$15:$P$114,9)=0,"",124)
AO7: 023 | AP7: =IF(VLOOKUP(AO7,請求データ入力!$B$15:$P$114,9)=0,"",186)
AO8: 024 | AP8: =IF(VLOOKUP(AO8,請求データ入力!$B$15:$P$114,9)=0,"",248)
AO9: 025 | AP9: =IF(VLOOKUP(AO9,請求データ入力!$B$15:$P$114,9)=0,"",310)
B10: ◆取引先名/コード | G10: =請求データ入力!$K$2 -> 72130 | L10: 登録番号 | R10: ◆計（税抜） | AO10: 026 | AP10: =IF(VLOOKUP(AO10,請求データ入力!$B$15:$P$114,9)=0,"",372)
L11: =請求データ入力!$K$6 -> 0 | V11: =請求データ入力!N35
B12: =請求データ入力!$F$2 -> 〒110-0012 東京都台東区竜泉3-40-4 | R12: ◆消費税 | AO12: 027 | AP12: =IF(VLOOKUP(AO12,請求データ入力!$B$15:$P$114,9)=0,"",434)
R13: （切捨） | T13: =請求データ入力!$O$11 -> 0.1 | V13: =請求データ入力!O35
B14: =請求データ入力!$F$6 -> 有限会社木村左官工業 | R14: ◆税込合計金額 | AO14: 028 | AP14: =IF(VLOOKUP(AO14,請求データ入力!$B$15:$P$114,9)=0,"",496)
V15: =請求データ入力!P35 | AC15: 明細 （ 有 ・ 無 ）
R16: ◆取引先担当者 | V16: ◆完成納品年月日 | AC16: 検 算 | AI16: INPUT | AO16: 029 | AP16: =IF(VLOOKUP(AO16,請求データ入力!$B$15:$P$114,9)=0,"",558)
B17: ="TEL："&請求データ入力!$K$4 -> TEL：090-4609-2757 | R17: =請求データ入力!F35 -> 0 | V17: =CONCATENATE(請求データ入力!C35,"/",請求データ入力!D35,"/",請求データ入力!E35) -> //
B18: ◆工事コード/工事名 | R18: ◆藤田建装担当者 | AO18: 030 | AP18: =IF(VLOOKUP(AO18,請求データ入力!$B$15:$P$114,9)=0,"",620)
B19: =請求データ入力!H35 -> 0 | G19: =請求データ入力!I35 -> 0 | R19: =請求データ入力!G35 -> 0 | V19: T№ | W19: =請求データ入力!Q35 -> 2602021
B22: ③ 請求明細書 | P22: ㈱藤田建装 経理管理 | AA22: 備 考
E23: ◆ 内 容 | N23: ◆ 数 量 | R23: ◆ 単 価 | V23: ◆ 金 額
B24: =B3 -> 0 | N24: =N3 -> 0 | P24: =P3 -> 0 | R24: =R3 -> 0 | V24: =V3
AA25: 差替No.
AA26: 未請求No.
AA27: 経理責任者 | AE27: 経理担当 | AI27: 現場担当
B31: ◆取引先名/コード | G31: =請求データ入力!$K$2 -> 72130 | L31: 登録番号 | R31: ◆計（税抜）
L32: =請求データ入力!$K$6 -> 0 | V32: =V11
B33: =請求データ入力!$F$2 -> 〒110-0012 東京都台東区竜泉3-40-4 | R33: ◆消費税
R34: （切捨） | T34: =請求データ入力!$O$11 -> 0.1 | V34: =V13
B35: =請求データ入力!$F$6 -> 有限会社木村左官工業 | R35: ◆税込合計金額
V36: =V15 | AC36: 明細 （ 有 ・ 無 ）
R37: ◆取引先担当者 | V37: ◆完成納品年月日 | AC37: 検 算 | AI37: INPUT
B38: ="TEL："&請求データ入力!$K$4 -> TEL：090-4609-2757 | R38: =R17 -> 0 | V38: =V17 -> //
B39: ◆工事コード/工事名 | R39: ◆藤田建装担当者
B40: =B19 -> 0 | G40: =G19 -> 0 | R40: =R19 -> 0 | V40: T№ | W40: =W19 -> 2602021
B43: ④ 管理伝票 | P43: ㈱藤田建装 事業部管理 | AA43: 備 考
E44: ◆ 内 容 | N44: ◆ 数 量 | R44: ◆ 単 価 | V44: ◆ 金 額
B45: =B24 -> 0 | N45: =N24 -> 0 | P45: =P24 -> 0 | R45: =R24 -> 0 | V45: =V24
AA46: 差替No.
AA47: 未請求No.
...

Sheet 個別031-040
B1: ② 納品書 （原価計算書） | P1: ㈱藤田建装 現場担当→課管理 | AA1: 備 考 | AM1: 331
E2: ◆ 内 容 | N2: ◆ 数 量 | R2: ◆ 単 価 | V2: ◆ 金 額 | AO2: 印刷範囲 | AP2: =IF(MAX($AP$5:$AP$19)=0,1,MAX($AP$5:$AP$19)) -> 1 | AQ2: 行目 | AR2: =IF(AP2=1,1,38) -> 1 | AS2: 列目まで印刷する
B3: =請求データ入力!J45 -> 0 | N3: =請求データ入力!K45 -> 0 | P3: =請求データ入力!L45 -> 0 | R3: =請求データ入力!M45 -> 0 | V3: =請求データ入力!N45
AA4: 差替No. | AO4: 伝票№連番 | AP4: 行数
AA5: 未請求No. | AO5: 031 | AP5: =IF(VLOOKUP(AO5,請求データ入力!$B$15:$P$114,9)=0,"",62)
AA6: 経理責任者 | AE6: 経理担当 | AI6: 現場担当 | AO6: 032 | AP6: =IF(VLOOKUP(AO6,請求データ入力!$B$15:$P$114,9)=0,"",124)
AO7: 033 | AP7: =IF(VLOOKUP(AO7,請求データ入力!$B$15:$P$114,9)=0,"",186)
AO8: 034 | AP8: =IF(VLOOKUP(AO8,請求データ入力!$B$15:$P$114,9)=0,"",248)
AO9: 035 | AP9: =IF(VLOOKUP(AO9,請求データ入力!$B$15:$P$114,9)=0,"",310)
B10: ◆取引先名/コード | G10: =請求データ入力!$K$2 -> 72130 | L10: 登録番号 | R10: ◆計（税抜） | AO10: 036 | AP10: =IF(VLOOKUP(AO10,請求データ入力!$B$15:$P$114,9)=0,"",372)
L11: =請求データ入力!$K$6 -> 0 | V11: =請求データ入力!N45
B12: =請求データ入力!$F$2 -> 〒110-0012 東京都台東区竜泉3-40-4 | R12: ◆消費税 | AO12: 037 | AP12: =IF(VLOOKUP(AO12,請求データ入力!$B$15:$P$114,9)=0,"",434)
R13: （切捨） | T13: =請求データ入力!$O$11 -> 0.1 | V13: =請求データ入力!O45
B14: =請求データ入力!$F$6 -> 有限会社木村左官工業 | R14: ◆税込合計金額 | AO14: 038 | AP14: =IF(VLOOKUP(AO14,請求データ入力!$B$15:$P$114,9)=0,"",496)
V15: =請求データ入力!P45 | AC15: 明細 （ 有 ・ 無 ）
R16: ◆取引先担当者 | V16: ◆完成納品年月日 | AC16: 検 算 | AI16: INPUT | AO16: 039 | AP16: =IF(VLOOKUP(AO16,請求データ入力!$B$15:$P$114,9)=0,"",558)
B17: ="TEL："&請求データ入力!$K$4 -> TEL：090-4609-2757 | R17: =請求データ入力!F45 -> 0 | V17: =CONCATENATE(請求データ入力!C45,"/",請求データ入力!D45,"/",請求データ入力!E45) -> //
B18: ◆工事コード/工事名 | R18: ◆藤田建装担当者 | AO18: 040 | AP18: =IF(VLOOKUP(AO18,請求データ入力!$B$15:$P$114,9)=0,"",620)
B19: =請求データ入力!H45 -> 0 | G19: =請求データ入力!I45 -> 0 | R19: =請求データ入力!G45 -> 0 | V19: T№ | W19: =請求データ入力!Q45 -> 2602031
B22: ③ 請求明細書 | P22: ㈱藤田建装 経理管理 | AA22: 備 考
E23: ◆ 内 容 | N23: ◆ 数 量 | R23: ◆ 単 価 | V23: ◆ 金 額
B24: =B3 -> 0 | N24: =N3 -> 0 | P24: =P3 -> 0 | R24: =R3 -> 0 | V24: =V3
AA25: 差替No.
AA26: 未請求No.
AA27: 経理責任者 | AE27: 経理担当 | AI27: 現場担当
B31: ◆取引先名/コード | G31: =請求データ入力!$K$2 -> 72130 | L31: 登録番号 | R31: ◆計（税抜）
L32: =請求データ入力!$K$6 -> 0 | V32: =V11
B33: =請求データ入力!$F$2 -> 〒110-0012 東京都台東区竜泉3-40-4 | R33: ◆消費税
R34: （切捨） | T34: =請求データ入力!$O$11 -> 0.1 | V34: =V13
B35: =請求データ入力!$F$6 -> 有限会社木村左官工業 | R35: ◆税込合計金額
V36: =V15 | AC36: 明細 （ 有 ・ 無 ）
R37: ◆取引先担当者 | V37: ◆完成納品年月日 | AC37: 検 算 | AI37: INPUT
B38: ="TEL："&請求データ入力!$K$4 -> TEL：090-4609-2757 | R38: =R17 -> 0 | V38: =V17 -> //
B39: ◆工事コード/工事名 | R39: ◆藤田建装担当者
B40: =B19 -> 0 | G40: =G19 -> 0 | R40: =R19 -> 0 | V40: T№ | W40: =W19 -> 2602031
B43: ④ 管理伝票 | P43: ㈱藤田建装 事業部管理 | AA43: 備 考
E44: ◆ 内 容 | N44: ◆ 数 量 | R44: ◆ 単 価 | V44: ◆ 金 額
B45: =B24 -> 0 | N45: =N24 -> 0 | P45: =P24 -> 0 | R45: =R24 -> 0 | V45: =V24
AA46: 差替No.
AA47: 未請求No.
...

Sheet 個別041-050
B1: ② 納品書 （原価計算書） | P1: ㈱藤田建装 現場担当→課管理 | AA1: 備 考 | AM1: 341
E2: ◆ 内 容 | N2: ◆ 数 量 | R2: ◆ 単 価 | V2: ◆ 金 額 | AO2: 印刷範囲 | AP2: =IF(MAX($AP$5:$AP$19)=0,1,MAX($AP$5:$AP$19)) -> 1 | AQ2: 行目 | AR2: =IF(AP2=1,1,38) -> 1 | AS2: 列目まで印刷する
B3: =請求データ入力!J55 -> 0 | N3: =請求データ入力!K55 -> 0 | P3: =請求データ入力!L55 -> 0 | R3: =請求データ入力!M55 -> 0 | V3: =請求データ入力!N55
AA4: 差替No. | AO4: 伝票№連番 | AP4: 行数
AA5: 未請求No. | AO5: 041 | AP5: =IF(VLOOKUP(AO5,請求データ入力!$B$15:$P$114,9)=0,"",62)
AA6: 経理責任者 | AE6: 経理担当 | AI6: 現場担当 | AO6: 042 | AP6: =IF(VLOOKUP(AO6,請求データ入力!$B$15:$P$114,9)=0,"",124)
AO7: 043 | AP7: =IF(VLOOKUP(AO7,請求データ入力!$B$15:$P$114,9)=0,"",186)
AO8: 044 | AP8: =IF(VLOOKUP(AO8,請求データ入力!$B$15:$P$114,9)=0,"",248)
AO9: 045 | AP9: =IF(VLOOKUP(AO9,請求データ入力!$B$15:$P$114,9)=0,"",310)
B10: ◆取引先名/コード | G10: =請求データ入力!$K$2 -> 72130 | L10: 登録番号 | R10: ◆計（税抜） | AO10: 046 | AP10: =IF(VLOOKUP(AO10,請求データ入力!$B$15:$P$114,9)=0,"",372)
L11: =請求データ入力!$K$6 -> 0 | V11: =請求データ入力!N55
B12: =請求データ入力!$F$2 -> 〒110-0012 東京都台東区竜泉3-40-4 | R12: ◆消費税 | AO12: 047 | AP12: =IF(VLOOKUP(AO12,請求データ入力!$B$15:$P$114,9)=0,"",434)
R13: （切捨） | T13: =請求データ入力!$O$11 -> 0.1 | V13: =請求データ入力!O55
B14: =請求データ入力!$F$6 -> 有限会社木村左官工業 | R14: ◆税込合計金額 | AO14: 048 | AP14: =IF(VLOOKUP(AO14,請求データ入力!$B$15:$P$114,9)=0,"",496)
V15: =請求データ入力!P55 | AC15: 明細 （ 有 ・ 無 ）
R16: ◆取引先担当者 | V16: ◆完成納品年月日 | AC16: 検 算 | AI16: INPUT | AO16: 049 | AP16: =IF(VLOOKUP(AO16,請求データ入力!$B$15:$P$114,9)=0,"",558)
B17: ="TEL："&請求データ入力!$K$4 -> TEL：090-4609-2757 | R17: =請求データ入力!F55 -> 0 | V17: =CONCATENATE(請求データ入力!C55,"/",請求データ入力!D55,"/",請求データ入力!E55) -> //
B18: ◆工事コード/工事名 | R18: ◆藤田建装担当者 | AO18: 050 | AP18: =IF(VLOOKUP(AO18,請求データ入力!$B$15:$P$114,9)=0,"",620)
B19: =請求データ入力!H55 -> 0 | G19: =請求データ入力!I55 -> 0 | R19: =請求データ入力!G55 -> 0 | V19: T№ | W19: =請求データ入力!Q55 -> 2602041
B22: ③ 請求明細書 | P22: ㈱藤田建装 経理管理 | AA22: 備 考
E23: ◆ 内 容 | N23: ◆ 数 量 | R23: ◆ 単 価 | V23: ◆ 金 額
B24: =B3 -> 0 | N24: =N3 -> 0 | P24: =P3 -> 0 | R24: =R3 -> 0 | V24: =V3
AA25: 差替No.
AA26: 未請求No.
AA27: 経理責任者 | AE27: 経理担当 | AI27: 現場担当
B31: ◆取引先名/コード | G31: =請求データ入力!$K$2 -> 72130 | L31: 登録番号 | R31: ◆計（税抜）
L32: =請求データ入力!$K$6 -> 0 | V32: =V11
B33: =請求データ入力!$F$2 -> 〒110-0012 東京都台東区竜泉3-40-4 | R33: ◆消費税
R34: （切捨） | T34: =請求データ入力!$O$11 -> 0.1 | V34: =V13
B35: =請求データ入力!$F$6 -> 有限会社木村左官工業 | R35: ◆税込合計金額
V36: =V15 | AC36: 明細 （ 有 ・ 無 ）
R37: ◆取引先担当者 | V37: ◆完成納品年月日 | AC37: 検 算 | AI37: INPUT
B38: ="TEL："&請求データ入力!$K$4 -> TEL：090-4609-2757 | R38: =R17 -> 0 | V38: =V17 -> //
B39: ◆工事コード/工事名 | R39: ◆藤田建装担当者
B40: =B19 -> 0 | G40: =G19 -> 0 | R40: =R19 -> 0 | V40: T№ | W40: =W19 -> 2602041
B43: ④ 管理伝票 | P43: ㈱藤田建装 事業部管理 | AA43: 備 考
E44: ◆ 内 容 | N44: ◆ 数 量 | R44: ◆ 単 価 | V44: ◆ 金 額
B45: =B24 -> 0 | N45: =N24 -> 0 | P45: =P24 -> 0 | R45: =R24 -> 0 | V45: =V24
AA46: 差替No.
AA47: 未請求No.
...

Sheet 個別051-060
B1: ② 納品書 （原価計算書） | P1: ㈱藤田建装 現場担当→課管理 | AA1: 備 考 | AM1: 351
E2: ◆ 内 容 | N2: ◆ 数 量 | R2: ◆ 単 価 | V2: ◆ 金 額 | AO2: 印刷範囲 | AP2: =IF(MAX($AP$5:$AP$19)=0,1,MAX($AP$5:$AP$19)) -> 1 | AQ2: 行目 | AR2: =IF(AP2=1,1,38) -> 1 | AS2: 列目まで印刷する
B3: =請求データ入力!J65 -> 0 | N3: =請求データ入力!K65 -> 0 | P3: =請求データ入力!L65 -> 0 | R3: =請求データ入力!M65 -> 0 | V3: =請求データ入力!N65
AA4: 差替No. | AO4: 伝票№連番 | AP4: 行数
AA5: 未請求No. | AO5: 051 | AP5: =IF(VLOOKUP(AO5,請求データ入力!$B$15:$P$114,9)=0,"",62)
AA6: 経理責任者 | AE6: 経理担当 | AI6: 現場担当 | AO6: 052 | AP6: =IF(VLOOKUP(AO6,請求データ入力!$B$15:$P$114,9)=0,"",124)
AO7: 053 | AP7: =IF(VLOOKUP(AO7,請求データ入力!$B$15:$P$114,9)=0,"",186)
AO8: 054 | AP8: =IF(VLOOKUP(AO8,請求データ入力!$B$15:$P$114,9)=0,"",248)
AO9: 055 | AP9: =IF(VLOOKUP(AO9,請求データ入力!$B$15:$P$114,9)=0,"",310)
B10: ◆取引先名/コード | G10: =請求データ入力!$K$2 -> 72130 | L10: 登録番号 | R10: ◆計（税抜） | AO10: 056 | AP10: =IF(VLOOKUP(AO10,請求データ入力!$B$15:$P$114,9)=0,"",372)
L11: =請求データ入力!$K$6 -> 0 | V11: =請求データ入力!N65
B12: =請求データ入力!$F$2 -> 〒110-0012 東京都台東区竜泉3-40-4 | R12: ◆消費税 | AO12: 057 | AP12: =IF(VLOOKUP(AO12,請求データ入力!$B$15:$P$114,9)=0,"",434)
R13: （切捨） | T13: =請求データ入力!$O$11 -> 0.1 | V13: =請求データ入力!O65
B14: =請求データ入力!$F$6 -> 有限会社木村左官工業 | R14: ◆税込合計金額 | AO14: 058 | AP14: =IF(VLOOKUP(AO14,請求データ入力!$B$15:$P$114,9)=0,"",496)
V15: =請求データ入力!P65 | AC15: 明細 （ 有 ・ 無 ）
R16: ◆取引先担当者 | V16: ◆完成納品年月日 | AC16: 検 算 | AI16: INPUT | AO16: 059 | AP16: =IF(VLOOKUP(AO16,請求データ入力!$B$15:$P$114,9)=0,"",558)
B17: ="TEL："&請求データ入力!$K$4 -> TEL：090-4609-2757 | R17: =請求データ入力!F65 -> 0 | V17: =CONCATENATE(請求データ入力!C65,"/",請求データ入力!D65,"/",請求データ入力!E65) -> //
B18: ◆工事コード/工事名 | R18: ◆藤田建装担当者 | AO18: 060 | AP18: =IF(VLOOKUP(AO18,請求データ入力!$B$15:$P$114,9)=0,"",620)
B19: =請求データ入力!H65 -> 0 | G19: =請求データ入力!I65 -> 0 | R19: =請求データ入力!G65 -> 0 | V19: T№ | W19: =請求データ入力!Q65 -> 2602051
B22: ③ 請求明細書 | P22: ㈱藤田建装 経理管理 | AA22: 備 考
E23: ◆ 内 容 | N23: ◆ 数 量 | R23: ◆ 単 価 | V23: ◆ 金 額
B24: =B3 -> 0 | N24: =N3 -> 0 | P24: =P3 -> 0 | R24: =R3 -> 0 | V24: =V3
AA25: 差替No.
AA26: 未請求No.
AA27: 経理責任者 | AE27: 経理担当 | AI27: 現場担当
B31: ◆取引先名/コード | G31: =請求データ入力!$K$2 -> 72130 | L31: 登録番号 | R31: ◆計（税抜）
L32: =請求データ入力!$K$6 -> 0 | V32: =V11
B33: =請求データ入力!$F$2 -> 〒110-0012 東京都台東区竜泉3-40-4 | R33: ◆消費税
R34: （切捨） | T34: =請求データ入力!$O$11 -> 0.1 | V34: =V13
B35: =請求データ入力!$F$6 -> 有限会社木村左官工業 | R35: ◆税込合計金額
V36: =V15 | AC36: 明細 （ 有 ・ 無 ）
R37: ◆取引先担当者 | V37: ◆完成納品年月日 | AC37: 検 算 | AI37: INPUT
B38: ="TEL："&請求データ入力!$K$4 -> TEL：090-4609-2757 | R38: =R17 -> 0 | V38: =V17 -> //
B39: ◆工事コード/工事名 | R39: ◆藤田建装担当者
B40: =B19 -> 0 | G40: =G19 -> 0 | R40: =R19 -> 0 | V40: T№ | W40: =W19 -> 2602051
B43: ④ 管理伝票 | P43: ㈱藤田建装 事業部管理 | AA43: 備 考
E44: ◆ 内 容 | N44: ◆ 数 量 | R44: ◆ 単 価 | V44: ◆ 金 額
B45: =B24 -> 0 | N45: =N24 -> 0 | P45: =P24 -> 0 | R45: =R24 -> 0 | V45: =V24
AA46: 差替No.
AA47: 未請求No.
...

Sheet 個別061-070
B1: ② 納品書 （原価計算書） | P1: ㈱藤田建装 現場担当→課管理 | AA1: 備 考 | AM1: 361
E2: ◆ 内 容 | N2: ◆ 数 量 | R2: ◆ 単 価 | V2: ◆ 金 額 | AO2: 印刷範囲 | AP2: =IF(MAX($AP$5:$AP$19)=0,1,MAX($AP$5:$AP$19)) -> 1 | AQ2: 行目 | AR2: =IF(AP2=1,1,38) -> 1 | AS2: 列目まで印刷する
B3: =請求データ入力!J75 -> 0 | N3: =請求データ入力!K75 -> 0 | P3: =請求データ入力!L75 -> 0 | R3: =請求データ入力!M75 -> 0 | V3: =請求データ入力!N75
AA4: 差替No. | AO4: 伝票№連番 | AP4: 行数
AA5: 未請求No. | AO5: 061 | AP5: =IF(VLOOKUP(AO5,請求データ入力!$B$15:$P$114,9)=0,"",62)
AA6: 経理責任者 | AE6: 経理担当 | AI6: 現場担当 | AO6: 062 | AP6: =IF(VLOOKUP(AO6,請求データ入力!$B$15:$P$114,9)=0,"",124)
AO7: 063 | AP7: =IF(VLOOKUP(AO7,請求データ入力!$B$15:$P$114,9)=0,"",186)
AO8: 064 | AP8: =IF(VLOOKUP(AO8,請求データ入力!$B$15:$P$114,9)=0,"",248)
AO9: 065 | AP9: =IF(VLOOKUP(AO9,請求データ入力!$B$15:$P$114,9)=0,"",310)
B10: ◆取引先名/コード | G10: =請求データ入力!$K$2 -> 72130 | L10: 登録番号 | R10: ◆計（税抜） | AO10: 066 | AP10: =IF(VLOOKUP(AO10,請求データ入力!$B$15:$P$114,9)=0,"",372)
L11: =請求データ入力!$K$6 -> 0 | V11: =請求データ入力!N75
B12: =請求データ入力!$F$2 -> 〒110-0012 東京都台東区竜泉3-40-4 | R12: ◆消費税 | AO12: 067 | AP12: =IF(VLOOKUP(AO12,請求データ入力!$B$15:$P$114,9)=0,"",434)
R13: （切捨） | T13: =請求データ入力!$O$11 -> 0.1 | V13: =請求データ入力!O75
B14: =請求データ入力!$F$6 -> 有限会社木村左官工業 | R14: ◆税込合計金額 | AO14: 068 | AP14: =IF(VLOOKUP(AO14,請求データ入力!$B$15:$P$114,9)=0,"",496)
V15: =請求データ入力!P75 | AC15: 明細 （ 有 ・ 無 ）
R16: ◆取引先担当者 | V16: ◆完成納品年月日 | AC16: 検 算 | AI16: INPUT | AO16: 069 | AP16: =IF(VLOOKUP(AO16,請求データ入力!$B$15:$P$114,9)=0,"",558)
B17: ="TEL："&請求データ入力!$K$4 -> TEL：090-4609-2757 | R17: =請求データ入力!F75 -> 0 | V17: =CONCATENATE(請求データ入力!C75,"/",請求データ入力!D75,"/",請求データ入力!E75) -> //
B18: ◆工事コード/工事名 | R18: ◆藤田建装担当者 | AO18: 070 | AP18: =IF(VLOOKUP(AO18,請求データ入力!$B$15:$P$114,9)=0,"",620)
B19: =請求データ入力!H75 -> 0 | G19: =請求データ入力!I75 -> 0 | R19: =請求データ入力!G75 -> 0 | V19: T№ | W19: =請求データ入力!Q75 -> 2602061
B22: ③ 請求明細書 | P22: ㈱藤田建装 経理管理 | AA22: 備 考
E23: ◆ 内 容 | N23: ◆ 数 量 | R23: ◆ 単 価 | V23: ◆ 金 額
B24: =B3 -> 0 | N24: =N3 -> 0 | P24: =P3 -> 0 | R24: =R3 -> 0 | V24: =V3
AA25: 差替No.
AA26: 未請求No.
AA27: 経理責任者 | AE27: 経理担当 | AI27: 現場担当
B31: ◆取引先名/コード | G31: =請求データ入力!$K$2 -> 72130 | L31: 登録番号 | R31: ◆計（税抜）
L32: =請求データ入力!$K$6 -> 0 | V32: =V11
B33: =請求データ入力!$F$2 -> 〒110-0012 東京都台東区竜泉3-40-4 | R33: ◆消費税
R34: （切捨） | T34: =請求データ入力!$O$11 -> 0.1 | V34: =V13
B35: =請求データ入力!$F$6 -> 有限会社木村左官工業 | R35: ◆税込合計金額
V36: =V15 | AC36: 明細 （ 有 ・ 無 ）
R37: ◆取引先担当者 | V37: ◆完成納品年月日 | AC37: 検 算 | AI37: INPUT
B38: ="TEL："&請求データ入力!$K$4 -> TEL：090-4609-2757 | R38: =R17 -> 0 | V38: =V17 -> //
B39: ◆工事コード/工事名 | R39: ◆藤田建装担当者
B40: =B19 -> 0 | G40: =G19 -> 0 | R40: =R19 -> 0 | V40: T№ | W40: =W19 -> 2602061
B43: ④ 管理伝票 | P43: ㈱藤田建装 事業部管理 | AA43: 備 考
E44: ◆ 内 容 | N44: ◆ 数 量 | R44: ◆ 単 価 | V44: ◆ 金 額
B45: =B24 -> 0 | N45: =N24 -> 0 | P45: =P24 -> 0 | R45: =R24 -> 0 | V45: =V24
AA46: 差替No.
AA47: 未請求No.
...

Sheet 個別071-080
B1: ② 納品書 （原価計算書） | P1: ㈱藤田建装 現場担当→課管理 | AA1: 備 考 | AM1: 371
E2: ◆ 内 容 | N2: ◆ 数 量 | R2: ◆ 単 価 | V2: ◆ 金 額 | AO2: 印刷範囲 | AP2: =IF(MAX($AP$5:$AP$19)=0,1,MAX($AP$5:$AP$19)) -> 1 | AQ2: 行目 | AR2: =IF(AP2=1,1,38) -> 1 | AS2: 列目まで印刷する
B3: =請求データ入力!J85 -> 0 | N3: =請求データ入力!K85 -> 0 | P3: =請求データ入力!L85 -> 0 | R3: =請求データ入力!M85 -> 0 | V3: =請求データ入力!N85
AA4: 差替No. | AO4: 伝票№連番 | AP4: 行数
AA5: 未請求No. | AO5: 071 | AP5: =IF(VLOOKUP(AO5,請求データ入力!$B$15:$P$114,9)=0,"",62)
AA6: 経理責任者 | AE6: 経理担当 | AI6: 現場担当 | AO6: 072 | AP6: =IF(VLOOKUP(AO6,請求データ入力!$B$15:$P$114,9)=0,"",124)
AO7: 073 | AP7: =IF(VLOOKUP(AO7,請求データ入力!$B$15:$P$114,9)=0,"",186)
AO8: 074 | AP8: =IF(VLOOKUP(AO8,請求データ入力!$B$15:$P$114,9)=0,"",248)
AO9: 075 | AP9: =IF(VLOOKUP(AO9,請求データ入力!$B$15:$P$114,9)=0,"",310)
B10: ◆取引先名/コード | G10: =請求データ入力!$K$2 -> 72130 | L10: 登録番号 | R10: ◆計（税抜） | AO10: 076 | AP10: =IF(VLOOKUP(AO10,請求データ入力!$B$15:$P$114,9)=0,"",372)
L11: =請求データ入力!$K$6 -> 0 | V11: =請求データ入力!N85
B12: =請求データ入力!$F$2 -> 〒110-0012 東京都台東区竜泉3-40-4 | R12: ◆消費税 | AO12: 077 | AP12: =IF(VLOOKUP(AO12,請求データ入力!$B$15:$P$114,9)=0,"",434)
R13: （切捨） | T13: =請求データ入力!$O$11 -> 0.1 | V13: =請求データ入力!O85
B14: =請求データ入力!$F$6 -> 有限会社木村左官工業 | R14: ◆税込合計金額 | AO14: 078 | AP14: =IF(VLOOKUP(AO14,請求データ入力!$B$15:$P$114,9)=0,"",496)
V15: =請求データ入力!P85 | AC15: 明細 （ 有 ・ 無 ）
R16: ◆取引先担当者 | V16: ◆完成納品年月日 | AC16: 検 算 | AI16: INPUT | AO16: 079 | AP16: =IF(VLOOKUP(AO16,請求データ入力!$B$15:$P$114,9)=0,"",558)
B17: ="TEL："&請求データ入力!$K$4 -> TEL：090-4609-2757 | R17: =請求データ入力!F85 -> 0 | V17: =CONCATENATE(請求データ入力!C85,"/",請求データ入力!D85,"/",請求データ入力!E85) -> //
B18: ◆工事コード/工事名 | R18: ◆藤田建装担当者 | AO18: 080 | AP18: =IF(VLOOKUP(AO18,請求データ入力!$B$15:$P$114,9)=0,"",620)
B19: =請求データ入力!H85 -> 0 | G19: =請求データ入力!I85 -> 0 | R19: =請求データ入力!G85 -> 0 | V19: T№ | W19: =請求データ入力!Q85 -> 2602071
B22: ③ 請求明細書 | P22: ㈱藤田建装 経理管理 | AA22: 備 考
E23: ◆ 内 容 | N23: ◆ 数 量 | R23: ◆ 単 価 | V23: ◆ 金 額
B24: =B3 -> 0 | N24: =N3 -> 0 | P24: =P3 -> 0 | R24: =R3 -> 0 | V24: =V3
AA25: 差替No.
AA26: 未請求No.
AA27: 経理責任者 | AE27: 経理担当 | AI27: 現場担当
B31: ◆取引先名/コード | G31: =請求データ入力!$K$2 -> 72130 | L31: 登録番号 | R31: ◆計（税抜）
L32: =請求データ入力!$K$6 -> 0 | V32: =V11
B33: =請求データ入力!$F$2 -> 〒110-0012 東京都台東区竜泉3-40-4 | R33: ◆消費税
R34: （切捨） | T34: =請求データ入力!$O$11 -> 0.1 | V34: =V13
B35: =請求データ入力!$F$6 -> 有限会社木村左官工業 | R35: ◆税込合計金額
V36: =V15 | AC36: 明細 （ 有 ・ 無 ）
R37: ◆取引先担当者 | V37: ◆完成納品年月日 | AC37: 検 算 | AI37: INPUT
B38: ="TEL："&請求データ入力!$K$4 -> TEL：090-4609-2757 | R38: =R17 -> 0 | V38: =V17 -> //
B39: ◆工事コード/工事名 | R39: ◆藤田建装担当者
B40: =B19 -> 0 | G40: =G19 -> 0 | R40: =R19 -> 0 | V40: T№ | W40: =W19 -> 2602071
B43: ④ 管理伝票 | P43: ㈱藤田建装 事業部管理 | AA43: 備 考
E44: ◆ 内 容 | N44: ◆ 数 量 | R44: ◆ 単 価 | V44: ◆ 金 額
B45: =B24 -> 0 | N45: =N24 -> 0 | P45: =P24 -> 0 | R45: =R24 -> 0 | V45: =V24
AA46: 差替No.
AA47: 未請求No.
...

Sheet 個別081-090
B1: ② 納品書 （原価計算書） | P1: ㈱藤田建装 現場担当→課管理 | AA1: 備 考 | AM1: 381
E2: ◆ 内 容 | N2: ◆ 数 量 | R2: ◆ 単 価 | V2: ◆ 金 額 | AO2: 印刷範囲 | AP2: =IF(MAX($AP$5:$AP$19)=0,1,MAX($AP$5:$AP$19)) -> 1 | AQ2: 行目 | AR2: =IF(AP2=1,1,38) -> 1 | AS2: 列目まで印刷する
B3: =請求データ入力!J95 -> 0 | N3: =請求データ入力!K95 -> 0 | P3: =請求データ入力!L95 -> 0 | R3: =請求データ入力!M95 -> 0 | V3: =請求データ入力!N95
AA4: 差替No. | AO4: 伝票№連番 | AP4: 行数
AA5: 未請求No. | AO5: 081 | AP5: =IF(VLOOKUP(AO5,請求データ入力!$B$15:$P$114,9)=0,"",62)
AA6: 経理責任者 | AE6: 経理担当 | AI6: 現場担当 | AO6: 082 | AP6: =IF(VLOOKUP(AO6,請求データ入力!$B$15:$P$114,9)=0,"",124)
AO7: 083 | AP7: =IF(VLOOKUP(AO7,請求データ入力!$B$15:$P$114,9)=0,"",186)
AO8: 084 | AP8: =IF(VLOOKUP(AO8,請求データ入力!$B$15:$P$114,9)=0,"",248)
AO9: 085 | AP9: =IF(VLOOKUP(AO9,請求データ入力!$B$15:$P$114,9)=0,"",310)
B10: ◆取引先名/コード | G10: =請求データ入力!$K$2 -> 72130 | L10: 登録番号 | R10: ◆計（税抜） | AO10: 086 | AP10: =IF(VLOOKUP(AO10,請求データ入力!$B$15:$P$114,9)=0,"",372)
L11: =請求データ入力!$K$6 -> 0 | V11: =請求データ入力!N95
B12: =請求データ入力!$F$2 -> 〒110-0012 東京都台東区竜泉3-40-4 | R12: ◆消費税 | AO12: 087 | AP12: =IF(VLOOKUP(AO12,請求データ入力!$B$15:$P$114,9)=0,"",434)
R13: （切捨） | T13: =請求データ入力!$O$11 -> 0.1 | V13: =請求データ入力!O95
B14: =請求データ入力!$F$6 -> 有限会社木村左官工業 | R14: ◆税込合計金額 | AO14: 088 | AP14: =IF(VLOOKUP(AO14,請求データ入力!$B$15:$P$114,9)=0,"",496)
V15: =請求データ入力!P95 | AC15: 明細 （ 有 ・ 無 ）
R16: ◆取引先担当者 | V16: ◆完成納品年月日 | AC16: 検 算 | AI16: INPUT | AO16: 089 | AP16: =IF(VLOOKUP(AO16,請求データ入力!$B$15:$P$114,9)=0,"",558)
B17: ="TEL："&請求データ入力!$K$4 -> TEL：090-4609-2757 | R17: =請求データ入力!F95 -> 0 | V17: =CONCATENATE(請求データ入力!C95,"/",請求データ入力!D95,"/",請求データ入力!E95) -> //
B18: ◆工事コード/工事名 | R18: ◆藤田建装担当者 | AO18: 090 | AP18: =IF(VLOOKUP(AO18,請求データ入力!$B$15:$P$114,9)=0,"",620)
B19: =請求データ入力!H95 -> 0 | G19: =請求データ入力!I95 -> 0 | R19: =請求データ入力!G95 -> 0 | V19: T№ | W19: =請求データ入力!Q95 -> 2602081
B22: ③ 請求明細書 | P22: ㈱藤田建装 経理管理 | AA22: 備 考
E23: ◆ 内 容 | N23: ◆ 数 量 | R23: ◆ 単 価 | V23: ◆ 金 額
B24: =B3 -> 0 | N24: =N3 -> 0 | P24: =P3 -> 0 | R24: =R3 -> 0 | V24: =V3
AA25: 差替No.
AA26: 未請求No.
AA27: 経理責任者 | AE27: 経理担当 | AI27: 現場担当
B31: ◆取引先名/コード | G31: =請求データ入力!$K$2 -> 72130 | L31: 登録番号 | R31: ◆計（税抜）
L32: =請求データ入力!$K$6 -> 0 | V32: =V11
B33: =請求データ入力!$F$2 -> 〒110-0012 東京都台東区竜泉3-40-4 | R33: ◆消費税
R34: （切捨） | T34: =請求データ入力!$O$11 -> 0.1 | V34: =V13
B35: =請求データ入力!$F$6 -> 有限会社木村左官工業 | R35: ◆税込合計金額
V36: =V15 | AC36: 明細 （ 有 ・ 無 ）
R37: ◆取引先担当者 | V37: ◆完成納品年月日 | AC37: 検 算 | AI37: INPUT
B38: ="TEL："&請求データ入力!$K$4 -> TEL：090-4609-2757 | R38: =R17 -> 0 | V38: =V17 -> //
B39: ◆工事コード/工事名 | R39: ◆藤田建装担当者
B40: =B19 -> 0 | G40: =G19 -> 0 | R40: =R19 -> 0 | V40: T№ | W40: =W19 -> 2602081
B43: ④ 管理伝票 | P43: ㈱藤田建装 事業部管理 | AA43: 備 考
E44: ◆ 内 容 | N44: ◆ 数 量 | R44: ◆ 単 価 | V44: ◆ 金 額
B45: =B24 -> 0 | N45: =N24 -> 0 | P45: =P24 -> 0 | R45: =R24 -> 0 | V45: =V24
AA46: 差替No.
AA47: 未請求No.
...

Sheet 個別091-100
B1: ② 納品書 （原価計算書） | P1: ㈱藤田建装 現場担当→課管理 | AA1: 備 考 | AM1: 391
E2: ◆ 内 容 | N2: ◆ 数 量 | R2: ◆ 単 価 | V2: ◆ 金 額 | AO2: 印刷範囲 | AP2: =IF(MAX($AP$5:$AP$19)=0,1,MAX($AP$5:$AP$19)) -> 1 | AQ2: 行目 | AR2: =IF(AP2=1,1,38) -> 1 | AS2: 列目まで印刷する
B3: =請求データ入力!J105 -> 0 | N3: =請求データ入力!K105 -> 0 | P3: =請求データ入力!L105 -> 0 | R3: =請求データ入力!M105 -> 0 | V3: =請求データ入力!N105
AA4: 差替No. | AO4: 伝票№連番 | AP4: 行数
AA5: 未請求No. | AO5: 091 | AP5: =IF(VLOOKUP(AO5,請求データ入力!$B$15:$P$114,9)=0,"",62)
AA6: 経理責任者 | AE6: 経理担当 | AI6: 現場担当 | AO6: 092 | AP6: =IF(VLOOKUP(AO6,請求データ入力!$B$15:$P$114,9)=0,"",124)
AO7: 093 | AP7: =IF(VLOOKUP(AO7,請求データ入力!$B$15:$P$114,9)=0,"",186)
AO8: 094 | AP8: =IF(VLOOKUP(AO8,請求データ入力!$B$15:$P$114,9)=0,"",248)
AO9: 095 | AP9: =IF(VLOOKUP(AO9,請求データ入力!$B$15:$P$114,9)=0,"",310)
B10: ◆取引先名/コード | G10: =請求データ入力!$K$2 -> 72130 | L10: 登録番号 | R10: ◆計（税抜） | AO10: 096 | AP10: =IF(VLOOKUP(AO10,請求データ入力!$B$15:$P$114,9)=0,"",372)
L11: =請求データ入力!$K$6 -> 0 | V11: =請求データ入力!N105
B12: =請求データ入力!$F$2 -> 〒110-0012 東京都台東区竜泉3-40-4 | R12: ◆消費税 | AO12: 097 | AP12: =IF(VLOOKUP(AO12,請求データ入力!$B$15:$P$114,9)=0,"",434)
R13: （切捨） | T13: =請求データ入力!$O$11 -> 0.1 | V13: =請求データ入力!O105
B14: =請求データ入力!$F$6 -> 有限会社木村左官工業 | R14: ◆税込合計金額 | AO14: 098 | AP14: =IF(VLOOKUP(AO14,請求データ入力!$B$15:$P$114,9)=0,"",496)
V15: =請求データ入力!P105 | AC15: 明細 （ 有 ・ 無 ）
R16: ◆取引先担当者 | V16: ◆完成納品年月日 | AC16: 検 算 | AI16: INPUT | AO16: 099 | AP16: =IF(VLOOKUP(AO16,請求データ入力!$B$15:$P$114,9)=0,"",558)
B17: ="TEL："&請求データ入力!$K$4 -> TEL：090-4609-2757 | R17: =請求データ入力!F105 -> 0 | V17: =CONCATENATE(請求データ入力!C105,"/",請求データ入力!D105,"/",請求データ入力!E105) -> //
B18: ◆工事コード/工事名 | R18: ◆藤田建装担当者 | AO18: 100 | AP18: =IF(VLOOKUP(AO18,請求データ入力!$B$15:$P$114,9)=0,"",620)
B19: =請求データ入力!H105 -> 0 | G19: =請求データ入力!I105 -> 0 | R19: =請求データ入力!G105 -> 0 | V19: T№ | W19: =請求データ入力!Q105 -> 2602091
B22: ③ 請求明細書 | P22: ㈱藤田建装 経理管理 | AA22: 備 考
E23: ◆ 内 容 | N23: ◆ 数 量 | R23: ◆ 単 価 | V23: ◆ 金 額
B24: =B3 -> 0 | N24: =N3 -> 0 | P24: =P3 -> 0 | R24: =R3 -> 0 | V24: =V3
AA25: 差替No.
AA26: 未請求No.
AA27: 経理責任者 | AE27: 経理担当 | AI27: 現場担当
B31: ◆取引先名/コード | G31: =請求データ入力!$K$2 -> 72130 | L31: 登録番号 | R31: ◆計（税抜）
L32: =請求データ入力!$K$6 -> 0 | V32: =V11
B33: =請求データ入力!$F$2 -> 〒110-0012 東京都台東区竜泉3-40-4 | R33: ◆消費税
R34: （切捨） | T34: =請求データ入力!$O$11 -> 0.1 | V34: =V13
B35: =請求データ入力!$F$6 -> 有限会社木村左官工業 | R35: ◆税込合計金額
V36: =V15 | AC36: 明細 （ 有 ・ 無 ）
R37: ◆取引先担当者 | V37: ◆完成納品年月日 | AC37: 検 算 | AI37: INPUT
B38: ="TEL："&請求データ入力!$K$4 -> TEL：090-4609-2757 | R38: =R17 -> 0 | V38: =V17 -> //
B39: ◆工事コード/工事名 | R39: ◆藤田建装担当者
B40: =B19 -> 0 | G40: =G19 -> 0 | R40: =R19 -> 0 | V40: T№ | W40: =W19 -> 2602091
B43: ④ 管理伝票 | P43: ㈱藤田建装 事業部管理 | AA43: 備 考
E44: ◆ 内 容 | N44: ◆ 数 量 | R44: ◆ 単 価 | V44: ◆ 金 額
B45: =B24 -> 0 | N45: =N24 -> 0 | P45: =P24 -> 0 | R45: =R24 -> 0 | V45: =V24
AA46: 差替No.
AA47: 未請求No.
...
